telegram.vendor.ptb_urllib3.urllib3.connectionpool - WARNING - Retrying (Retry(total=2, connect=None, read=None, redirect=None)) after connection broken by 'ConnectTimeoutError(<telegram.vendor.ptb_urllib3.urllib3.contrib.socks.SOCKSHTTPSConnectionPool object at 0x000001FB66FEA940>, 'Connect timed out. (connect timeout=5.0)')': /bot806287477:AAGRPsodiHUxnxz2zWZAUcUeUiTkIaqkMIo/getUpdates
telegram.vendor.ptb_urllib3.urllib3.connectionpool - WARNING - Retrying (Retry(total=1, connect=None, read=None, redirect=None)) after connection broken by 'NewConnectionError('<telegram.vendor.ptb_urllib3.urllib3.contrib.socks.SOCKSHTTPSConnection object at 0x000001FB67029A20>: Failed to establish a new connection: [Errno 11001] getaddrinfo failed',)': /bot806287477:AAGRPsodiHUxnxz2zWZAUcUeUiTkIaqkMIo/getUpdates
telegram.vendor.ptb_urllib3.urllib3.connectionpool - WARNING - Retrying (Retry(total=0, connect=None, read=None, redirect=None)) after connection broken by 'NewConnectionError('<telegram.vendor.ptb_urllib3.urllib3.contrib.socks.SOCKSHTTPSConnection object at 0x000001FB670297B8>: Failed to establish a new connection: [Errno 11001] getaddrinfo failed',)': /bot806287477:AAGRPsodiHUxnxz2zWZAUcUeUiTkIaqkMIo/getUpdates
telegram.ext.updater - ERROR - Error while getting Updates: urllib3 HTTPError SOCKSHTTPSConnectionPool(host='api.telegram.org', port=443): Max retries exceeded with url: /bot806287477:AAGRPsodiHUxnxz2zWZAUcUeUiTkIaqkMIo/getUpdates (Caused by NewConnectionError('<telegram.vendor.ptb_urllib3.urllib3.contrib.socks.SOCKSHTTPSConnection object at 0x000001FB67029F60>: Failed to establish a new connection: [Errno 11001] getaddrinfo failed',))
telegram.ext.dispatcher - ERROR - No error handlers are registered, logging exception.
Traceback (most recent call last):
  File "C:\projects\lesson2\learn-homework-1\untitled\lib\site-packages\telegram\vendor\ptb_urllib3\urllib3\contrib\socks.py", line 88, in _new_conn
    **extra_kw
  File "C:\projects\lesson2\learn-homework-1\untitled\lib\site-packages\socks.py", line 180, in create_connection
    for r in socket.getaddrinfo(proxy_addr, proxy_port, 0, socket.SOCK_STREAM):
  File "C:\Users\Anna\AppData\Local\Programs\Python\Python36\lib\socket.py", line 745, in getaddrinfo
    for res in _socket.getaddrinfo(host, port, family, type, proto, flags):
socket.gaierror: [Errno 11001] getaddrinfo failed

During handling of the above exception, another exception occurred:

Traceback (most recent call last):
  File "C:\projects\lesson2\learn-homework-1\untitled\lib\site-packages\telegram\vendor\ptb_urllib3\urllib3\connectionpool.py", line 617, in urlopen
    chunked=chunked)
  File "C:\projects\lesson2\learn-homework-1\untitled\lib\site-packages\telegram\vendor\ptb_urllib3\urllib3\connectionpool.py", line 360, in _make_request
    self._validate_conn(conn)
  File "C:\projects\lesson2\learn-homework-1\untitled\lib\site-packages\telegram\vendor\ptb_urllib3\urllib3\connectionpool.py", line 857, in _validate_conn
    super(HTTPSConnectionPool, self)._validate_conn(conn)
  File "C:\projects\lesson2\learn-homework-1\untitled\lib\site-packages\telegram\vendor\ptb_urllib3\urllib3\connectionpool.py", line 289, in _validate_conn
    conn.connect()
  File "C:\projects\lesson2\learn-homework-1\untitled\lib\site-packages\telegram\vendor\ptb_urllib3\urllib3\connection.py", line 284, in connect
    conn = self._new_conn()
  File "C:\projects\lesson2\learn-homework-1\untitled\lib\site-packages\telegram\vendor\ptb_urllib3\urllib3\contrib\socks.py", line 120, in _new_conn
    self, "Failed to establish a new connection: %s" % e)
telegram.vendor.ptb_urllib3.urllib3.exceptions.NewConnectionError: <telegram.vendor.ptb_urllib3.urllib3.contrib.socks.SOCKSHTTPSConnection object at 0x000001FB67029F60>: Failed to establish a new connection: [Errno 11001] getaddrinfo failed

During handling of the above exception, another exception occurred:

Traceback (most recent call last):
  File "C:\projects\lesson2\learn-homework-1\untitled\lib\site-packages\telegram\utils\request.py", line 203, in _request_wrapper
    resp = self._con_pool.request(*args, **kwargs)
  File "C:\projects\lesson2\learn-homework-1\untitled\lib\site-packages\telegram\vendor\ptb_urllib3\urllib3\request.py", line 70, in request
    **urlopen_kw)
  File "C:\projects\lesson2\learn-homework-1\untitled\lib\site-packages\telegram\vendor\ptb_urllib3\urllib3\request.py", line 148, in request_encode_body
    return self.urlopen(method, url, **extra_kw)
  File "C:\projects\lesson2\learn-homework-1\untitled\lib\site-packages\telegram\vendor\ptb_urllib3\urllib3\poolmanager.py", line 244, in urlopen
    response = conn.urlopen(method, u.request_uri, **kw)
  File "C:\projects\lesson2\learn-homework-1\untitled\lib\site-packages\telegram\vendor\ptb_urllib3\urllib3\connectionpool.py", line 695, in urlopen
    **response_kw)
  File "C:\projects\lesson2\learn-homework-1\untitled\lib\site-packages\telegram\vendor\ptb_urllib3\urllib3\connectionpool.py", line 695, in urlopen
    **response_kw)
  File "C:\projects\lesson2\learn-homework-1\untitled\lib\site-packages\telegram\vendor\ptb_urllib3\urllib3\connectionpool.py", line 695, in urlopen
    **response_kw)
  File "C:\projects\lesson2\learn-homework-1\untitled\lib\site-packages\telegram\vendor\ptb_urllib3\urllib3\connectionpool.py", line 666, in urlopen
    _stacktrace=sys.exc_info()[2])
  File "C:\projects\lesson2\learn-homework-1\untitled\lib\site-packages\telegram\vendor\ptb_urllib3\urllib3\util\retry.py", line 376, in increment
    raise MaxRetryError(_pool, url, error or ResponseError(cause))
telegram.vendor.ptb_urllib3.urllib3.exceptions.MaxRetryError: SOCKSHTTPSConnectionPool(host='api.telegram.org', port=443): Max retries exceeded with url: /bot806287477:AAGRPsodiHUxnxz2zWZAUcUeUiTkIaqkMIo/getUpdates (Caused by NewConnectionError('<telegram.vendor.ptb_urllib3.urllib3.contrib.socks.SOCKSHTTPSConnection object at 0x000001FB67029F60>: Failed to establish a new connection: [Errno 11001] getaddrinfo failed',))

During handling of the above exception, another exception occurred:

Traceback (most recent call last):
  File "C:\projects\lesson2\learn-homework-1\untitled\lib\site-packages\telegram\ext\updater.py", line 319, in _network_loop_retry
    if not action_cb():
  File "C:\projects\lesson2\learn-homework-1\untitled\lib\site-packages\telegram\ext\updater.py", line 280, in polling_action_cb
    allowed_updates=allowed_updates)
  File "C:\projects\lesson2\learn-homework-1\untitled\lib\site-packages\telegram\bot.py", line 65, in decorator
    result = func(self, *args, **kwargs)
  File "C:\projects\lesson2\learn-homework-1\untitled\lib\site-packages\telegram\bot.py", line 1975, in get_updates
    result = self._request.post(url, data, timeout=float(read_latency) + float(timeout))
  File "C:\projects\lesson2\learn-homework-1\untitled\lib\site-packages\telegram\utils\request.py", line 309, in post
    headers={'Content-Type': 'application/json'})
  File "C:\projects\lesson2\learn-homework-1\untitled\lib\site-packages\telegram\utils\request.py", line 209, in _request_wrapper
    raise NetworkError('urllib3 HTTPError {0}'.format(error))
telegram.error.NetworkError: urllib3 HTTPError SOCKSHTTPSConnectionPool(host='api.telegram.org', port=443): Max retries exceeded with url: /bot806287477:AAGRPsodiHUxnxz2zWZAUcUeUiTkIaqkMIo/getUpdates (Caused by NewConnectionError('<telegram.vendor.ptb_urllib3.urllib3.contrib.socks.SOCKSHTTPSConnection object at 0x000001FB67029F60>: Failed to establish a new connection: [Errno 11001] getaddrinfo failed',))
telegram.vendor.ptb_urllib3.urllib3.connectionpool - WARNING - Retrying (Retry(total=2, connect=None, read=None, redirect=None)) after connection broken by 'NewConnectionError('<telegram.vendor.ptb_urllib3.urllib3.contrib.socks.SOCKSHTTPSConnection object at 0x000001FB67029390>: Failed to establish a new connection: [Errno 11001] getaddrinfo failed',)': /bot806287477:AAGRPsodiHUxnxz2zWZAUcUeUiTkIaqkMIo/getUpdates
telegram.vendor.ptb_urllib3.urllib3.connectionpool - WARNING - Retrying (Retry(total=1, connect=None, read=None, redirect=None)) after connection broken by 'NewConnectionError('<telegram.vendor.ptb_urllib3.urllib3.contrib.socks.SOCKSHTTPSConnection object at 0x000001FB66FEA898>: Failed to establish a new connection: [Errno 11001] getaddrinfo failed',)': /bot806287477:AAGRPsodiHUxnxz2zWZAUcUeUiTkIaqkMIo/getUpdates
telegram.vendor.ptb_urllib3.urllib3.connectionpool - WARNING - Retrying (Retry(total=0, connect=None, read=None, redirect=None)) after connection broken by 'NewConnectionError('<telegram.vendor.ptb_urllib3.urllib3.contrib.socks.SOCKSHTTPSConnection object at 0x000001FB678654E0>: Failed to establish a new connection: [Errno 11001] getaddrinfo failed',)': /bot806287477:AAGRPsodiHUxnxz2zWZAUcUeUiTkIaqkMIo/getUpdates
telegram.ext.updater - ERROR - Error while getting Updates: urllib3 HTTPError SOCKSHTTPSConnectionPool(host='api.telegram.org', port=443): Max retries exceeded with url: /bot806287477:AAGRPsodiHUxnxz2zWZAUcUeUiTkIaqkMIo/getUpdates (Caused by NewConnectionError('<telegram.vendor.ptb_urllib3.urllib3.contrib.socks.SOCKSHTTPSConnection object at 0x000001FB67865630>: Failed to establish a new connection: [Errno 11001] getaddrinfo failed',))
telegram.ext.dispatcher - ERROR - No error handlers are registered, logging exception.
Traceback (most recent call last):
  File "C:\projects\lesson2\learn-homework-1\untitled\lib\site-packages\telegram\vendor\ptb_urllib3\urllib3\contrib\socks.py", line 88, in _new_conn
    **extra_kw
  File "C:\projects\lesson2\learn-homework-1\untitled\lib\site-packages\socks.py", line 180, in create_connection
    for r in socket.getaddrinfo(proxy_addr, proxy_port, 0, socket.SOCK_STREAM):
  File "C:\Users\Anna\AppData\Local\Programs\Python\Python36\lib\socket.py", line 745, in getaddrinfo
    for res in _socket.getaddrinfo(host, port, family, type, proto, flags):
socket.gaierror: [Errno 11001] getaddrinfo failed

During handling of the above exception, another exception occurred:

Traceback (most recent call last):
  File "C:\projects\lesson2\learn-homework-1\untitled\lib\site-packages\telegram\vendor\ptb_urllib3\urllib3\connectionpool.py", line 617, in urlopen
    chunked=chunked)
  File "C:\projects\lesson2\learn-homework-1\untitled\lib\site-packages\telegram\vendor\ptb_urllib3\urllib3\connectionpool.py", line 360, in _make_request
    self._validate_conn(conn)
  File "C:\projects\lesson2\learn-homework-1\untitled\lib\site-packages\telegram\vendor\ptb_urllib3\urllib3\connectionpool.py", line 857, in _validate_conn
    super(HTTPSConnectionPool, self)._validate_conn(conn)
  File "C:\projects\lesson2\learn-homework-1\untitled\lib\site-packages\telegram\vendor\ptb_urllib3\urllib3\connectionpool.py", line 289, in _validate_conn
    conn.connect()
  File "C:\projects\lesson2\learn-homework-1\untitled\lib\site-packages\telegram\vendor\ptb_urllib3\urllib3\connection.py", line 284, in connect
    conn = self._new_conn()
  File "C:\projects\lesson2\learn-homework-1\untitled\lib\site-packages\telegram\vendor\ptb_urllib3\urllib3\contrib\socks.py", line 120, in _new_conn
    self, "Failed to establish a new connection: %s" % e)
telegram.vendor.ptb_urllib3.urllib3.exceptions.NewConnectionError: <telegram.vendor.ptb_urllib3.urllib3.contrib.socks.SOCKSHTTPSConnection object at 0x000001FB67865630>: Failed to establish a new connection: [Errno 11001] getaddrinfo failed

During handling of the above exception, another exception occurred:

Traceback (most recent call last):
  File "C:\projects\lesson2\learn-homework-1\untitled\lib\site-packages\telegram\utils\request.py", line 203, in _request_wrapper
    resp = self._con_pool.request(*args, **kwargs)
  File "C:\projects\lesson2\learn-homework-1\untitled\lib\site-packages\telegram\vendor\ptb_urllib3\urllib3\request.py", line 70, in request
    **urlopen_kw)
  File "C:\projects\lesson2\learn-homework-1\untitled\lib\site-packages\telegram\vendor\ptb_urllib3\urllib3\request.py", line 148, in request_encode_body
    return self.urlopen(method, url, **extra_kw)
  File "C:\projects\lesson2\learn-homework-1\untitled\lib\site-packages\telegram\vendor\ptb_urllib3\urllib3\poolmanager.py", line 244, in urlopen
    response = conn.urlopen(method, u.request_uri, **kw)
  File "C:\projects\lesson2\learn-homework-1\untitled\lib\site-packages\telegram\vendor\ptb_urllib3\urllib3\connectionpool.py", line 695, in urlopen
    **response_kw)
  File "C:\projects\lesson2\learn-homework-1\untitled\lib\site-packages\telegram\vendor\ptb_urllib3\urllib3\connectionpool.py", line 695, in urlopen
    **response_kw)
  File "C:\projects\lesson2\learn-homework-1\untitled\lib\site-packages\telegram\vendor\ptb_urllib3\urllib3\connectionpool.py", line 695, in urlopen
    **response_kw)
  File "C:\projects\lesson2\learn-homework-1\untitled\lib\site-packages\telegram\vendor\ptb_urllib3\urllib3\connectionpool.py", line 666, in urlopen
    _stacktrace=sys.exc_info()[2])
  File "C:\projects\lesson2\learn-homework-1\untitled\lib\site-packages\telegram\vendor\ptb_urllib3\urllib3\util\retry.py", line 376, in increment
    raise MaxRetryError(_pool, url, error or ResponseError(cause))
telegram.vendor.ptb_urllib3.urllib3.exceptions.MaxRetryError: SOCKSHTTPSConnectionPool(host='api.telegram.org', port=443): Max retries exceeded with url: /bot806287477:AAGRPsodiHUxnxz2zWZAUcUeUiTkIaqkMIo/getUpdates (Caused by NewConnectionError('<telegram.vendor.ptb_urllib3.urllib3.contrib.socks.SOCKSHTTPSConnection object at 0x000001FB67865630>: Failed to establish a new connection: [Errno 11001] getaddrinfo failed',))

During handling of the above exception, another exception occurred:

Traceback (most recent call last):
  File "C:\projects\lesson2\learn-homework-1\untitled\lib\site-packages\telegram\ext\updater.py", line 319, in _network_loop_retry
    if not action_cb():
  File "C:\projects\lesson2\learn-homework-1\untitled\lib\site-packages\telegram\ext\updater.py", line 280, in polling_action_cb
    allowed_updates=allowed_updates)
  File "C:\projects\lesson2\learn-homework-1\untitled\lib\site-packages\telegram\bot.py", line 65, in decorator
    result = func(self, *args, **kwargs)
  File "C:\projects\lesson2\learn-homework-1\untitled\lib\site-packages\telegram\bot.py", line 1975, in get_updates
    result = self._request.post(url, data, timeout=float(read_latency) + float(timeout))
  File "C:\projects\lesson2\learn-homework-1\untitled\lib\site-packages\telegram\utils\request.py", line 309, in post
    headers={'Content-Type': 'application/json'})
  File "C:\projects\lesson2\learn-homework-1\untitled\lib\site-packages\telegram\utils\request.py", line 209, in _request_wrapper
    raise NetworkError('urllib3 HTTPError {0}'.format(error))
telegram.error.NetworkError: urllib3 HTTPError SOCKSHTTPSConnectionPool(host='api.telegram.org', port=443): Max retries exceeded with url: /bot806287477:AAGRPsodiHUxnxz2zWZAUcUeUiTkIaqkMIo/getUpdates (Caused by NewConnectionError('<telegram.vendor.ptb_urllib3.urllib3.contrib.socks.SOCKSHTTPSConnection object at 0x000001FB67865630>: Failed to establish a new connection: [Errno 11001] getaddrinfo failed',))
telegram.vendor.ptb_urllib3.urllib3.connectionpool - WARNING - Retrying (Retry(total=2, connect=None, read=None, redirect=None)) after connection broken by 'NewConnectionError('<telegram.vendor.ptb_urllib3.urllib3.contrib.socks.SOCKSHTTPSConnection object at 0x000001FB67029B38>: Failed to establish a new connection: [Errno 11001] getaddrinfo failed',)': /bot806287477:AAGRPsodiHUxnxz2zWZAUcUeUiTkIaqkMIo/getUpdates
telegram.vendor.ptb_urllib3.urllib3.connectionpool - WARNING - Retrying (Retry(total=1, connect=None, read=None, redirect=None)) after connection broken by 'NewConnectionError('<telegram.vendor.ptb_urllib3.urllib3.contrib.socks.SOCKSHTTPSConnection object at 0x000001FB670296A0>: Failed to establish a new connection: [Errno 11001] getaddrinfo failed',)': /bot806287477:AAGRPsodiHUxnxz2zWZAUcUeUiTkIaqkMIo/getUpdates
telegram.vendor.ptb_urllib3.urllib3.connectionpool - WARNING - Retrying (Retry(total=0, connect=None, read=None, redirect=None)) after connection broken by 'NewConnectionError('<telegram.vendor.ptb_urllib3.urllib3.contrib.socks.SOCKSHTTPSConnection object at 0x000001FB67029550>: Failed to establish a new connection: [Errno 11001] getaddrinfo failed',)': /bot806287477:AAGRPsodiHUxnxz2zWZAUcUeUiTkIaqkMIo/getUpdates
telegram.ext.updater - ERROR - Error while getting Updates: urllib3 HTTPError SOCKSHTTPSConnectionPool(host='api.telegram.org', port=443): Max retries exceeded with url: /bot806287477:AAGRPsodiHUxnxz2zWZAUcUeUiTkIaqkMIo/getUpdates (Caused by NewConnectionError('<telegram.vendor.ptb_urllib3.urllib3.contrib.socks.SOCKSHTTPSConnection object at 0x000001FB67029780>: Failed to establish a new connection: [Errno 11001] getaddrinfo failed',))
telegram.ext.dispatcher - ERROR - No error handlers are registered, logging exception.
Traceback (most recent call last):
  File "C:\projects\lesson2\learn-homework-1\untitled\lib\site-packages\telegram\vendor\ptb_urllib3\urllib3\contrib\socks.py", line 88, in _new_conn
    **extra_kw
  File "C:\projects\lesson2\learn-homework-1\untitled\lib\site-packages\socks.py", line 180, in create_connection
    for r in socket.getaddrinfo(proxy_addr, proxy_port, 0, socket.SOCK_STREAM):
  File "C:\Users\Anna\AppData\Local\Programs\Python\Python36\lib\socket.py", line 745, in getaddrinfo
    for res in _socket.getaddrinfo(host, port, family, type, proto, flags):
socket.gaierror: [Errno 11001] getaddrinfo failed

During handling of the above exception, another exception occurred:

Traceback (most recent call last):
  File "C:\projects\lesson2\learn-homework-1\untitled\lib\site-packages\telegram\vendor\ptb_urllib3\urllib3\connectionpool.py", line 617, in urlopen
    chunked=chunked)
  File "C:\projects\lesson2\learn-homework-1\untitled\lib\site-packages\telegram\vendor\ptb_urllib3\urllib3\connectionpool.py", line 360, in _make_request
    self._validate_conn(conn)
  File "C:\projects\lesson2\learn-homework-1\untitled\lib\site-packages\telegram\vendor\ptb_urllib3\urllib3\connectionpool.py", line 857, in _validate_conn
    super(HTTPSConnectionPool, self)._validate_conn(conn)
  File "C:\projects\lesson2\learn-homework-1\untitled\lib\site-packages\telegram\vendor\ptb_urllib3\urllib3\connectionpool.py", line 289, in _validate_conn
    conn.connect()
  File "C:\projects\lesson2\learn-homework-1\untitled\lib\site-packages\telegram\vendor\ptb_urllib3\urllib3\connection.py", line 284, in connect
    conn = self._new_conn()
  File "C:\projects\lesson2\learn-homework-1\untitled\lib\site-packages\telegram\vendor\ptb_urllib3\urllib3\contrib\socks.py", line 120, in _new_conn
    self, "Failed to establish a new connection: %s" % e)
telegram.vendor.ptb_urllib3.urllib3.exceptions.NewConnectionError: <telegram.vendor.ptb_urllib3.urllib3.contrib.socks.SOCKSHTTPSConnection object at 0x000001FB67029780>: Failed to establish a new connection: [Errno 11001] getaddrinfo failed

During handling of the above exception, another exception occurred:

Traceback (most recent call last):
  File "C:\projects\lesson2\learn-homework-1\untitled\lib\site-packages\telegram\utils\request.py", line 203, in _request_wrapper
    resp = self._con_pool.request(*args, **kwargs)
  File "C:\projects\lesson2\learn-homework-1\untitled\lib\site-packages\telegram\vendor\ptb_urllib3\urllib3\request.py", line 70, in request
    **urlopen_kw)
  File "C:\projects\lesson2\learn-homework-1\untitled\lib\site-packages\telegram\vendor\ptb_urllib3\urllib3\request.py", line 148, in request_encode_body
    return self.urlopen(method, url, **extra_kw)
  File "C:\projects\lesson2\learn-homework-1\untitled\lib\site-packages\telegram\vendor\ptb_urllib3\urllib3\poolmanager.py", line 244, in urlopen
    response = conn.urlopen(method, u.request_uri, **kw)
  File "C:\projects\lesson2\learn-homework-1\untitled\lib\site-packages\telegram\vendor\ptb_urllib3\urllib3\connectionpool.py", line 695, in urlopen
    **response_kw)
  File "C:\projects\lesson2\learn-homework-1\untitled\lib\site-packages\telegram\vendor\ptb_urllib3\urllib3\connectionpool.py", line 695, in urlopen
    **response_kw)
  File "C:\projects\lesson2\learn-homework-1\untitled\lib\site-packages\telegram\vendor\ptb_urllib3\urllib3\connectionpool.py", line 695, in urlopen
    **response_kw)
  File "C:\projects\lesson2\learn-homework-1\untitled\lib\site-packages\telegram\vendor\ptb_urllib3\urllib3\connectionpool.py", line 666, in urlopen
    _stacktrace=sys.exc_info()[2])
  File "C:\projects\lesson2\learn-homework-1\untitled\lib\site-packages\telegram\vendor\ptb_urllib3\urllib3\util\retry.py", line 376, in increment
    raise MaxRetryError(_pool, url, error or ResponseError(cause))
telegram.vendor.ptb_urllib3.urllib3.exceptions.MaxRetryError: SOCKSHTTPSConnectionPool(host='api.telegram.org', port=443): Max retries exceeded with url: /bot806287477:AAGRPsodiHUxnxz2zWZAUcUeUiTkIaqkMIo/getUpdates (Caused by NewConnectionError('<telegram.vendor.ptb_urllib3.urllib3.contrib.socks.SOCKSHTTPSConnection object at 0x000001FB67029780>: Failed to establish a new connection: [Errno 11001] getaddrinfo failed',))

During handling of the above exception, another exception occurred:

Traceback (most recent call last):
  File "C:\projects\lesson2\learn-homework-1\untitled\lib\site-packages\telegram\ext\updater.py", line 319, in _network_loop_retry
    if not action_cb():
  File "C:\projects\lesson2\learn-homework-1\untitled\lib\site-packages\telegram\ext\updater.py", line 280, in polling_action_cb
    allowed_updates=allowed_updates)
  File "C:\projects\lesson2\learn-homework-1\untitled\lib\site-packages\telegram\bot.py", line 65, in decorator
    result = func(self, *args, **kwargs)
  File "C:\projects\lesson2\learn-homework-1\untitled\lib\site-packages\telegram\bot.py", line 1975, in get_updates
    result = self._request.post(url, data, timeout=float(read_latency) + float(timeout))
  File "C:\projects\lesson2\learn-homework-1\untitled\lib\site-packages\telegram\utils\request.py", line 309, in post
    headers={'Content-Type': 'application/json'})
  File "C:\projects\lesson2\learn-homework-1\untitled\lib\site-packages\telegram\utils\request.py", line 209, in _request_wrapper
    raise NetworkError('urllib3 HTTPError {0}'.format(error))
telegram.error.NetworkError: urllib3 HTTPError SOCKSHTTPSConnectionPool(host='api.telegram.org', port=443): Max retries exceeded with url: /bot806287477:AAGRPsodiHUxnxz2zWZAUcUeUiTkIaqkMIo/getUpdates (Caused by NewConnectionError('<telegram.vendor.ptb_urllib3.urllib3.contrib.socks.SOCKSHTTPSConnection object at 0x000001FB67029780>: Failed to establish a new connection: [Errno 11001] getaddrinfo failed',))
telegram.vendor.ptb_urllib3.urllib3.connectionpool - WARNING - Retrying (Retry(total=2, connect=None, read=None, redirect=None)) after connection broken by 'NewConnectionError('<telegram.vendor.ptb_urllib3.urllib3.contrib.socks.SOCKSHTTPSConnection object at 0x000001FB670298D0>: Failed to establish a new connection: [Errno 11001] getaddrinfo failed',)': /bot806287477:AAGRPsodiHUxnxz2zWZAUcUeUiTkIaqkMIo/getUpdates
telegram.vendor.ptb_urllib3.urllib3.connectionpool - WARNING - Retrying (Retry(total=1, connect=None, read=None, redirect=None)) after connection broken by 'NewConnectionError('<telegram.vendor.ptb_urllib3.urllib3.contrib.socks.SOCKSHTTPSConnection object at 0x000001FB67856588>: Failed to establish a new connection: [Errno 11001] getaddrinfo failed',)': /bot806287477:AAGRPsodiHUxnxz2zWZAUcUeUiTkIaqkMIo/getUpdates
telegram.vendor.ptb_urllib3.urllib3.connectionpool - WARNING - Retrying (Retry(total=0, connect=None, read=None, redirect=None)) after connection broken by 'NewConnectionError('<telegram.vendor.ptb_urllib3.urllib3.contrib.socks.SOCKSHTTPSConnection object at 0x000001FB67856898>: Failed to establish a new connection: [Errno 11001] getaddrinfo failed',)': /bot806287477:AAGRPsodiHUxnxz2zWZAUcUeUiTkIaqkMIo/getUpdates
telegram.ext.updater - ERROR - Error while getting Updates: urllib3 HTTPError SOCKSHTTPSConnectionPool(host='api.telegram.org', port=443): Max retries exceeded with url: /bot806287477:AAGRPsodiHUxnxz2zWZAUcUeUiTkIaqkMIo/getUpdates (Caused by NewConnectionError('<telegram.vendor.ptb_urllib3.urllib3.contrib.socks.SOCKSHTTPSConnection object at 0x000001FB67856978>: Failed to establish a new connection: [Errno 11001] getaddrinfo failed',))
telegram.ext.dispatcher - ERROR - No error handlers are registered, logging exception.
Traceback (most recent call last):
  File "C:\projects\lesson2\learn-homework-1\untitled\lib\site-packages\telegram\vendor\ptb_urllib3\urllib3\contrib\socks.py", line 88, in _new_conn
    **extra_kw
  File "C:\projects\lesson2\learn-homework-1\untitled\lib\site-packages\socks.py", line 180, in create_connection
    for r in socket.getaddrinfo(proxy_addr, proxy_port, 0, socket.SOCK_STREAM):
  File "C:\Users\Anna\AppData\Local\Programs\Python\Python36\lib\socket.py", line 745, in getaddrinfo
    for res in _socket.getaddrinfo(host, port, family, type, proto, flags):
socket.gaierror: [Errno 11001] getaddrinfo failed

During handling of the above exception, another exception occurred:

Traceback (most recent call last):
  File "C:\projects\lesson2\learn-homework-1\untitled\lib\site-packages\telegram\vendor\ptb_urllib3\urllib3\connectionpool.py", line 617, in urlopen
    chunked=chunked)
  File "C:\projects\lesson2\learn-homework-1\untitled\lib\site-packages\telegram\vendor\ptb_urllib3\urllib3\connectionpool.py", line 360, in _make_request
    self._validate_conn(conn)
  File "C:\projects\lesson2\learn-homework-1\untitled\lib\site-packages\telegram\vendor\ptb_urllib3\urllib3\connectionpool.py", line 857, in _validate_conn
    super(HTTPSConnectionPool, self)._validate_conn(conn)
  File "C:\projects\lesson2\learn-homework-1\untitled\lib\site-packages\telegram\vendor\ptb_urllib3\urllib3\connectionpool.py", line 289, in _validate_conn
    conn.connect()
  File "C:\projects\lesson2\learn-homework-1\untitled\lib\site-packages\telegram\vendor\ptb_urllib3\urllib3\connection.py", line 284, in connect
    conn = self._new_conn()
  File "C:\projects\lesson2\learn-homework-1\untitled\lib\site-packages\telegram\vendor\ptb_urllib3\urllib3\contrib\socks.py", line 120, in _new_conn
    self, "Failed to establish a new connection: %s" % e)
telegram.vendor.ptb_urllib3.urllib3.exceptions.NewConnectionError: <telegram.vendor.ptb_urllib3.urllib3.contrib.socks.SOCKSHTTPSConnection object at 0x000001FB67856978>: Failed to establish a new connection: [Errno 11001] getaddrinfo failed

During handling of the above exception, another exception occurred:

Traceback (most recent call last):
  File "C:\projects\lesson2\learn-homework-1\untitled\lib\site-packages\telegram\utils\request.py", line 203, in _request_wrapper
    resp = self._con_pool.request(*args, **kwargs)
  File "C:\projects\lesson2\learn-homework-1\untitled\lib\site-packages\telegram\vendor\ptb_urllib3\urllib3\request.py", line 70, in request
    **urlopen_kw)
  File "C:\projects\lesson2\learn-homework-1\untitled\lib\site-packages\telegram\vendor\ptb_urllib3\urllib3\request.py", line 148, in request_encode_body
    return self.urlopen(method, url, **extra_kw)
  File "C:\projects\lesson2\learn-homework-1\untitled\lib\site-packages\telegram\vendor\ptb_urllib3\urllib3\poolmanager.py", line 244, in urlopen
    response = conn.urlopen(method, u.request_uri, **kw)
  File "C:\projects\lesson2\learn-homework-1\untitled\lib\site-packages\telegram\vendor\ptb_urllib3\urllib3\connectionpool.py", line 695, in urlopen
    **response_kw)
  File "C:\projects\lesson2\learn-homework-1\untitled\lib\site-packages\telegram\vendor\ptb_urllib3\urllib3\connectionpool.py", line 695, in urlopen
    **response_kw)
  File "C:\projects\lesson2\learn-homework-1\untitled\lib\site-packages\telegram\vendor\ptb_urllib3\urllib3\connectionpool.py", line 695, in urlopen
    **response_kw)
  File "C:\projects\lesson2\learn-homework-1\untitled\lib\site-packages\telegram\vendor\ptb_urllib3\urllib3\connectionpool.py", line 666, in urlopen
    _stacktrace=sys.exc_info()[2])
  File "C:\projects\lesson2\learn-homework-1\untitled\lib\site-packages\telegram\vendor\ptb_urllib3\urllib3\util\retry.py", line 376, in increment
    raise MaxRetryError(_pool, url, error or ResponseError(cause))
telegram.vendor.ptb_urllib3.urllib3.exceptions.MaxRetryError: SOCKSHTTPSConnectionPool(host='api.telegram.org', port=443): Max retries exceeded with url: /bot806287477:AAGRPsodiHUxnxz2zWZAUcUeUiTkIaqkMIo/getUpdates (Caused by NewConnectionError('<telegram.vendor.ptb_urllib3.urllib3.contrib.socks.SOCKSHTTPSConnection object at 0x000001FB67856978>: Failed to establish a new connection: [Errno 11001] getaddrinfo failed',))

During handling of the above exception, another exception occurred:

Traceback (most recent call last):
  File "C:\projects\lesson2\learn-homework-1\untitled\lib\site-packages\telegram\ext\updater.py", line 319, in _network_loop_retry
    if not action_cb():
  File "C:\projects\lesson2\learn-homework-1\untitled\lib\site-packages\telegram\ext\updater.py", line 280, in polling_action_cb
    allowed_updates=allowed_updates)
  File "C:\projects\lesson2\learn-homework-1\untitled\lib\site-packages\telegram\bot.py", line 65, in decorator
    result = func(self, *args, **kwargs)
  File "C:\projects\lesson2\learn-homework-1\untitled\lib\site-packages\telegram\bot.py", line 1975, in get_updates
    result = self._request.post(url, data, timeout=float(read_latency) + float(timeout))
  File "C:\projects\lesson2\learn-homework-1\untitled\lib\site-packages\telegram\utils\request.py", line 309, in post
    headers={'Content-Type': 'application/json'})
  File "C:\projects\lesson2\learn-homework-1\untitled\lib\site-packages\telegram\utils\request.py", line 209, in _request_wrapper
    raise NetworkError('urllib3 HTTPError {0}'.format(error))
telegram.error.NetworkError: urllib3 HTTPError SOCKSHTTPSConnectionPool(host='api.telegram.org', port=443): Max retries exceeded with url: /bot806287477:AAGRPsodiHUxnxz2zWZAUcUeUiTkIaqkMIo/getUpdates (Caused by NewConnectionError('<telegram.vendor.ptb_urllib3.urllib3.contrib.socks.SOCKSHTTPSConnection object at 0x000001FB67856978>: Failed to establish a new connection: [Errno 11001] getaddrinfo failed',))
telegram.vendor.ptb_urllib3.urllib3.connectionpool - WARNING - Retrying (Retry(total=2, connect=None, read=None, redirect=None)) after connection broken by 'NewConnectionError('<telegram.vendor.ptb_urllib3.urllib3.contrib.socks.SOCKSHTTPSConnection object at 0x000001FB67856FD0>: Failed to establish a new connection: [Errno 11001] getaddrinfo failed',)': /bot806287477:AAGRPsodiHUxnxz2zWZAUcUeUiTkIaqkMIo/getUpdates
telegram.vendor.ptb_urllib3.urllib3.connectionpool - WARNING - Retrying (Retry(total=1, connect=None, read=None, redirect=None)) after connection broken by 'NewConnectionError('<telegram.vendor.ptb_urllib3.urllib3.contrib.socks.SOCKSHTTPSConnection object at 0x000001FB678564E0>: Failed to establish a new connection: [Errno 11001] getaddrinfo failed',)': /bot806287477:AAGRPsodiHUxnxz2zWZAUcUeUiTkIaqkMIo/getUpdates
telegram.vendor.ptb_urllib3.urllib3.connectionpool - WARNING - Retrying (Retry(total=0, connect=None, read=None, redirect=None)) after connection broken by 'NewConnectionError('<telegram.vendor.ptb_urllib3.urllib3.contrib.socks.SOCKSHTTPSConnection object at 0x000001FB67856940>: Failed to establish a new connection: [Errno 11001] getaddrinfo failed',)': /bot806287477:AAGRPsodiHUxnxz2zWZAUcUeUiTkIaqkMIo/getUpdates
telegram.ext.updater - ERROR - Error while getting Updates: urllib3 HTTPError SOCKSHTTPSConnectionPool(host='api.telegram.org', port=443): Max retries exceeded with url: /bot806287477:AAGRPsodiHUxnxz2zWZAUcUeUiTkIaqkMIo/getUpdates (Caused by NewConnectionError('<telegram.vendor.ptb_urllib3.urllib3.contrib.socks.SOCKSHTTPSConnection object at 0x000001FB67856E80>: Failed to establish a new connection: [Errno 11001] getaddrinfo failed',))
telegram.ext.dispatcher - ERROR - No error handlers are registered, logging exception.
Traceback (most recent call last):
  File "C:\projects\lesson2\learn-homework-1\untitled\lib\site-packages\telegram\vendor\ptb_urllib3\urllib3\contrib\socks.py", line 88, in _new_conn
    **extra_kw
  File "C:\projects\lesson2\learn-homework-1\untitled\lib\site-packages\socks.py", line 180, in create_connection
    for r in socket.getaddrinfo(proxy_addr, proxy_port, 0, socket.SOCK_STREAM):
  File "C:\Users\Anna\AppData\Local\Programs\Python\Python36\lib\socket.py", line 745, in getaddrinfo
    for res in _socket.getaddrinfo(host, port, family, type, proto, flags):
socket.gaierror: [Errno 11001] getaddrinfo failed

During handling of the above exception, another exception occurred:

Traceback (most recent call last):
  File "C:\projects\lesson2\learn-homework-1\untitled\lib\site-packages\telegram\vendor\ptb_urllib3\urllib3\connectionpool.py", line 617, in urlopen
    chunked=chunked)
  File "C:\projects\lesson2\learn-homework-1\untitled\lib\site-packages\telegram\vendor\ptb_urllib3\urllib3\connectionpool.py", line 360, in _make_request
    self._validate_conn(conn)
  File "C:\projects\lesson2\learn-homework-1\untitled\lib\site-packages\telegram\vendor\ptb_urllib3\urllib3\connectionpool.py", line 857, in _validate_conn
    super(HTTPSConnectionPool, self)._validate_conn(conn)
  File "C:\projects\lesson2\learn-homework-1\untitled\lib\site-packages\telegram\vendor\ptb_urllib3\urllib3\connectionpool.py", line 289, in _validate_conn
    conn.connect()
  File "C:\projects\lesson2\learn-homework-1\untitled\lib\site-packages\telegram\vendor\ptb_urllib3\urllib3\connection.py", line 284, in connect
    conn = self._new_conn()
  File "C:\projects\lesson2\learn-homework-1\untitled\lib\site-packages\telegram\vendor\ptb_urllib3\urllib3\contrib\socks.py", line 120, in _new_conn
    self, "Failed to establish a new connection: %s" % e)
telegram.vendor.ptb_urllib3.urllib3.exceptions.NewConnectionError: <telegram.vendor.ptb_urllib3.urllib3.contrib.socks.SOCKSHTTPSConnection object at 0x000001FB67856E80>: Failed to establish a new connection: [Errno 11001] getaddrinfo failed

During handling of the above exception, another exception occurred:

Traceback (most recent call last):
  File "C:\projects\lesson2\learn-homework-1\untitled\lib\site-packages\telegram\utils\request.py", line 203, in _request_wrapper
    resp = self._con_pool.request(*args, **kwargs)
  File "C:\projects\lesson2\learn-homework-1\untitled\lib\site-packages\telegram\vendor\ptb_urllib3\urllib3\request.py", line 70, in request
    **urlopen_kw)
  File "C:\projects\lesson2\learn-homework-1\untitled\lib\site-packages\telegram\vendor\ptb_urllib3\urllib3\request.py", line 148, in request_encode_body
    return self.urlopen(method, url, **extra_kw)
  File "C:\projects\lesson2\learn-homework-1\untitled\lib\site-packages\telegram\vendor\ptb_urllib3\urllib3\poolmanager.py", line 244, in urlopen
    response = conn.urlopen(method, u.request_uri, **kw)
  File "C:\projects\lesson2\learn-homework-1\untitled\lib\site-packages\telegram\vendor\ptb_urllib3\urllib3\connectionpool.py", line 695, in urlopen
    **response_kw)
  File "C:\projects\lesson2\learn-homework-1\untitled\lib\site-packages\telegram\vendor\ptb_urllib3\urllib3\connectionpool.py", line 695, in urlopen
    **response_kw)
  File "C:\projects\lesson2\learn-homework-1\untitled\lib\site-packages\telegram\vendor\ptb_urllib3\urllib3\connectionpool.py", line 695, in urlopen
    **response_kw)
  File "C:\projects\lesson2\learn-homework-1\untitled\lib\site-packages\telegram\vendor\ptb_urllib3\urllib3\connectionpool.py", line 666, in urlopen
    _stacktrace=sys.exc_info()[2])
  File "C:\projects\lesson2\learn-homework-1\untitled\lib\site-packages\telegram\vendor\ptb_urllib3\urllib3\util\retry.py", line 376, in increment
    raise MaxRetryError(_pool, url, error or ResponseError(cause))
telegram.vendor.ptb_urllib3.urllib3.exceptions.MaxRetryError: SOCKSHTTPSConnectionPool(host='api.telegram.org', port=443): Max retries exceeded with url: /bot806287477:AAGRPsodiHUxnxz2zWZAUcUeUiTkIaqkMIo/getUpdates (Caused by NewConnectionError('<telegram.vendor.ptb_urllib3.urllib3.contrib.socks.SOCKSHTTPSConnection object at 0x000001FB67856E80>: Failed to establish a new connection: [Errno 11001] getaddrinfo failed',))

During handling of the above exception, another exception occurred:

Traceback (most recent call last):
  File "C:\projects\lesson2\learn-homework-1\untitled\lib\site-packages\telegram\ext\updater.py", line 319, in _network_loop_retry
    if not action_cb():
  File "C:\projects\lesson2\learn-homework-1\untitled\lib\site-packages\telegram\ext\updater.py", line 280, in polling_action_cb
    allowed_updates=allowed_updates)
  File "C:\projects\lesson2\learn-homework-1\untitled\lib\site-packages\telegram\bot.py", line 65, in decorator
    result = func(self, *args, **kwargs)
  File "C:\projects\lesson2\learn-homework-1\untitled\lib\site-packages\telegram\bot.py", line 1975, in get_updates
    result = self._request.post(url, data, timeout=float(read_latency) + float(timeout))
  File "C:\projects\lesson2\learn-homework-1\untitled\lib\site-packages\telegram\utils\request.py", line 309, in post
    headers={'Content-Type': 'application/json'})
  File "C:\projects\lesson2\learn-homework-1\untitled\lib\site-packages\telegram\utils\request.py", line 209, in _request_wrapper
    raise NetworkError('urllib3 HTTPError {0}'.format(error))
telegram.error.NetworkError: urllib3 HTTPError SOCKSHTTPSConnectionPool(host='api.telegram.org', port=443): Max retries exceeded with url: /bot806287477:AAGRPsodiHUxnxz2zWZAUcUeUiTkIaqkMIo/getUpdates (Caused by NewConnectionError('<telegram.vendor.ptb_urllib3.urllib3.contrib.socks.SOCKSHTTPSConnection object at 0x000001FB67856E80>: Failed to establish a new connection: [Errno 11001] getaddrinfo failed',))
telegram.vendor.ptb_urllib3.urllib3.connectionpool - WARNING - Retrying (Retry(total=2, connect=None, read=None, redirect=None)) after connection broken by 'ConnectTimeoutError(<telegram.vendor.ptb_urllib3.urllib3.contrib.socks.SOCKSHTTPSConnection object at 0x000001FB6786D160>, 'Connection to api.telegram.org timed out. (connect timeout=5.0)')': /bot806287477:AAGRPsodiHUxnxz2zWZAUcUeUiTkIaqkMIo/getUpdates
telegram.vendor.ptb_urllib3.urllib3.connectionpool - WARNING - Retrying (Retry(total=1, connect=None, read=None, redirect=None)) after connection broken by 'NewConnectionError('<telegram.vendor.ptb_urllib3.urllib3.contrib.socks.SOCKSHTTPSConnection object at 0x000001FB6786DFD0>: Failed to establish a new connection: [Errno 11001] getaddrinfo failed',)': /bot806287477:AAGRPsodiHUxnxz2zWZAUcUeUiTkIaqkMIo/getUpdates
telegram.vendor.ptb_urllib3.urllib3.connectionpool - WARNING - Retrying (Retry(total=0, connect=None, read=None, redirect=None)) after connection broken by 'NewConnectionError('<telegram.vendor.ptb_urllib3.urllib3.contrib.socks.SOCKSHTTPSConnection object at 0x000001FB6786D9B0>: Failed to establish a new connection: [Errno 11001] getaddrinfo failed',)': /bot806287477:AAGRPsodiHUxnxz2zWZAUcUeUiTkIaqkMIo/getUpdates
telegram.ext.updater - ERROR - Error while getting Updates: urllib3 HTTPError SOCKSHTTPSConnectionPool(host='api.telegram.org', port=443): Max retries exceeded with url: /bot806287477:AAGRPsodiHUxnxz2zWZAUcUeUiTkIaqkMIo/getUpdates (Caused by NewConnectionError('<telegram.vendor.ptb_urllib3.urllib3.contrib.socks.SOCKSHTTPSConnection object at 0x000001FB678565F8>: Failed to establish a new connection: [Errno 11001] getaddrinfo failed',))
telegram.ext.dispatcher - ERROR - No error handlers are registered, logging exception.
Traceback (most recent call last):
  File "C:\projects\lesson2\learn-homework-1\untitled\lib\site-packages\socks.py", line 809, in connect
    negotiate(self, dest_addr, dest_port)
  File "C:\projects\lesson2\learn-homework-1\untitled\lib\site-packages\socks.py", line 444, in _negotiate_SOCKS5
    self, CONNECT, dest_addr)
  File "C:\projects\lesson2\learn-homework-1\untitled\lib\site-packages\socks.py", line 520, in _SOCKS5_request
    resolved = self._write_SOCKS5_address(dst, writer)
  File "C:\projects\lesson2\learn-homework-1\untitled\lib\site-packages\socks.py", line 576, in _write_SOCKS5_address
    socket.AI_ADDRCONFIG)
  File "C:\Users\Anna\AppData\Local\Programs\Python\Python36\lib\socket.py", line 745, in getaddrinfo
    for res in _socket.getaddrinfo(host, port, family, type, proto, flags):
socket.gaierror: [Errno 11001] getaddrinfo failed

During handling of the above exception, another exception occurred:

Traceback (most recent call last):
  File "C:\projects\lesson2\learn-homework-1\untitled\lib\site-packages\telegram\vendor\ptb_urllib3\urllib3\contrib\socks.py", line 88, in _new_conn
    **extra_kw
  File "C:\projects\lesson2\learn-homework-1\untitled\lib\site-packages\socks.py", line 209, in create_connection
    raise err
  File "C:\projects\lesson2\learn-homework-1\untitled\lib\site-packages\socks.py", line 199, in create_connection
    sock.connect((remote_host, remote_port))
  File "C:\projects\lesson2\learn-homework-1\untitled\lib\site-packages\socks.py", line 47, in wrapper
    return function(*args, **kwargs)
  File "C:\projects\lesson2\learn-homework-1\untitled\lib\site-packages\socks.py", line 814, in connect
    raise GeneralProxyError("Socket error", error)
socks.GeneralProxyError: Socket error: [Errno 11001] getaddrinfo failed

During handling of the above exception, another exception occurred:

Traceback (most recent call last):
  File "C:\projects\lesson2\learn-homework-1\untitled\lib\site-packages\telegram\vendor\ptb_urllib3\urllib3\connectionpool.py", line 617, in urlopen
    chunked=chunked)
  File "C:\projects\lesson2\learn-homework-1\untitled\lib\site-packages\telegram\vendor\ptb_urllib3\urllib3\connectionpool.py", line 360, in _make_request
    self._validate_conn(conn)
  File "C:\projects\lesson2\learn-homework-1\untitled\lib\site-packages\telegram\vendor\ptb_urllib3\urllib3\connectionpool.py", line 857, in _validate_conn
    super(HTTPSConnectionPool, self)._validate_conn(conn)
  File "C:\projects\lesson2\learn-homework-1\untitled\lib\site-packages\telegram\vendor\ptb_urllib3\urllib3\connectionpool.py", line 289, in _validate_conn
    conn.connect()
  File "C:\projects\lesson2\learn-homework-1\untitled\lib\site-packages\telegram\vendor\ptb_urllib3\urllib3\connection.py", line 284, in connect
    conn = self._new_conn()
  File "C:\projects\lesson2\learn-homework-1\untitled\lib\site-packages\telegram\vendor\ptb_urllib3\urllib3\contrib\socks.py", line 110, in _new_conn
    "Failed to establish a new connection: %s" % error
telegram.vendor.ptb_urllib3.urllib3.exceptions.NewConnectionError: <telegram.vendor.ptb_urllib3.urllib3.contrib.socks.SOCKSHTTPSConnection object at 0x000001FB678565F8>: Failed to establish a new connection: [Errno 11001] getaddrinfo failed

During handling of the above exception, another exception occurred:

Traceback (most recent call last):
  File "C:\projects\lesson2\learn-homework-1\untitled\lib\site-packages\telegram\utils\request.py", line 203, in _request_wrapper
    resp = self._con_pool.request(*args, **kwargs)
  File "C:\projects\lesson2\learn-homework-1\untitled\lib\site-packages\telegram\vendor\ptb_urllib3\urllib3\request.py", line 70, in request
    **urlopen_kw)
  File "C:\projects\lesson2\learn-homework-1\untitled\lib\site-packages\telegram\vendor\ptb_urllib3\urllib3\request.py", line 148, in request_encode_body
    return self.urlopen(method, url, **extra_kw)
  File "C:\projects\lesson2\learn-homework-1\untitled\lib\site-packages\telegram\vendor\ptb_urllib3\urllib3\poolmanager.py", line 244, in urlopen
    response = conn.urlopen(method, u.request_uri, **kw)
  File "C:\projects\lesson2\learn-homework-1\untitled\lib\site-packages\telegram\vendor\ptb_urllib3\urllib3\connectionpool.py", line 695, in urlopen
    **response_kw)
  File "C:\projects\lesson2\learn-homework-1\untitled\lib\site-packages\telegram\vendor\ptb_urllib3\urllib3\connectionpool.py", line 695, in urlopen
    **response_kw)
  File "C:\projects\lesson2\learn-homework-1\untitled\lib\site-packages\telegram\vendor\ptb_urllib3\urllib3\connectionpool.py", line 695, in urlopen
    **response_kw)
  File "C:\projects\lesson2\learn-homework-1\untitled\lib\site-packages\telegram\vendor\ptb_urllib3\urllib3\connectionpool.py", line 666, in urlopen
    _stacktrace=sys.exc_info()[2])
  File "C:\projects\lesson2\learn-homework-1\untitled\lib\site-packages\telegram\vendor\ptb_urllib3\urllib3\util\retry.py", line 376, in increment
    raise MaxRetryError(_pool, url, error or ResponseError(cause))
telegram.vendor.ptb_urllib3.urllib3.exceptions.MaxRetryError: SOCKSHTTPSConnectionPool(host='api.telegram.org', port=443): Max retries exceeded with url: /bot806287477:AAGRPsodiHUxnxz2zWZAUcUeUiTkIaqkMIo/getUpdates (Caused by NewConnectionError('<telegram.vendor.ptb_urllib3.urllib3.contrib.socks.SOCKSHTTPSConnection object at 0x000001FB678565F8>: Failed to establish a new connection: [Errno 11001] getaddrinfo failed',))

During handling of the above exception, another exception occurred:

Traceback (most recent call last):
  File "C:\projects\lesson2\learn-homework-1\untitled\lib\site-packages\telegram\ext\updater.py", line 319, in _network_loop_retry
    if not action_cb():
  File "C:\projects\lesson2\learn-homework-1\untitled\lib\site-packages\telegram\ext\updater.py", line 280, in polling_action_cb
    allowed_updates=allowed_updates)
  File "C:\projects\lesson2\learn-homework-1\untitled\lib\site-packages\telegram\bot.py", line 65, in decorator
    result = func(self, *args, **kwargs)
  File "C:\projects\lesson2\learn-homework-1\untitled\lib\site-packages\telegram\bot.py", line 1975, in get_updates
    result = self._request.post(url, data, timeout=float(read_latency) + float(timeout))
  File "C:\projects\lesson2\learn-homework-1\untitled\lib\site-packages\telegram\utils\request.py", line 309, in post
    headers={'Content-Type': 'application/json'})
  File "C:\projects\lesson2\learn-homework-1\untitled\lib\site-packages\telegram\utils\request.py", line 209, in _request_wrapper
    raise NetworkError('urllib3 HTTPError {0}'.format(error))
telegram.error.NetworkError: urllib3 HTTPError SOCKSHTTPSConnectionPool(host='api.telegram.org', port=443): Max retries exceeded with url: /bot806287477:AAGRPsodiHUxnxz2zWZAUcUeUiTkIaqkMIo/getUpdates (Caused by NewConnectionError('<telegram.vendor.ptb_urllib3.urllib3.contrib.socks.SOCKSHTTPSConnection object at 0x000001FB678565F8>: Failed to establish a new connection: [Errno 11001] getaddrinfo failed',))
telegram.vendor.ptb_urllib3.urllib3.connectionpool - WARNING - Retrying (Retry(total=2, connect=None, read=None, redirect=None)) after connection broken by 'ConnectTimeoutError(<telegram.vendor.ptb_urllib3.urllib3.contrib.socks.SOCKSHTTPSConnection object at 0x000001FB68A4F4A8>, 'Connection to api.telegram.org timed out. (connect timeout=5.0)')': /bot806287477:AAGRPsodiHUxnxz2zWZAUcUeUiTkIaqkMIo/getUpdates
telegram.vendor.ptb_urllib3.urllib3.connectionpool - WARNING - Retrying (Retry(total=1, connect=None, read=None, redirect=None)) after connection broken by 'NewConnectionError('<telegram.vendor.ptb_urllib3.urllib3.contrib.socks.SOCKSHTTPSConnection object at 0x000001FB67865CF8>: Failed to establish a new connection: [Errno 11004] getaddrinfo failed',)': /bot806287477:AAGRPsodiHUxnxz2zWZAUcUeUiTkIaqkMIo/getUpdates
telegram.vendor.ptb_urllib3.urllib3.connectionpool - WARNING - Retrying (Retry(total=0, connect=None, read=None, redirect=None)) after connection broken by 'NewConnectionError('<telegram.vendor.ptb_urllib3.urllib3.contrib.socks.SOCKSHTTPSConnection object at 0x000001FB67865320>: Failed to establish a new connection: [Errno 11004] getaddrinfo failed',)': /bot806287477:AAGRPsodiHUxnxz2zWZAUcUeUiTkIaqkMIo/getUpdates
telegram.ext.updater - ERROR - Error while getting Updates: urllib3 HTTPError SOCKSHTTPSConnectionPool(host='api.telegram.org', port=443): Max retries exceeded with url: /bot806287477:AAGRPsodiHUxnxz2zWZAUcUeUiTkIaqkMIo/getUpdates (Caused by NewConnectionError('<telegram.vendor.ptb_urllib3.urllib3.contrib.socks.SOCKSHTTPSConnection object at 0x000001FB670097F0>: Failed to establish a new connection: [Errno 11004] getaddrinfo failed',))
telegram.ext.dispatcher - ERROR - No error handlers are registered, logging exception.
Traceback (most recent call last):
  File "C:\projects\lesson2\learn-homework-1\untitled\lib\site-packages\socks.py", line 809, in connect
    negotiate(self, dest_addr, dest_port)
  File "C:\projects\lesson2\learn-homework-1\untitled\lib\site-packages\socks.py", line 444, in _negotiate_SOCKS5
    self, CONNECT, dest_addr)
  File "C:\projects\lesson2\learn-homework-1\untitled\lib\site-packages\socks.py", line 520, in _SOCKS5_request
    resolved = self._write_SOCKS5_address(dst, writer)
  File "C:\projects\lesson2\learn-homework-1\untitled\lib\site-packages\socks.py", line 576, in _write_SOCKS5_address
    socket.AI_ADDRCONFIG)
  File "C:\Users\Anna\AppData\Local\Programs\Python\Python36\lib\socket.py", line 745, in getaddrinfo
    for res in _socket.getaddrinfo(host, port, family, type, proto, flags):
socket.gaierror: [Errno 11004] getaddrinfo failed

During handling of the above exception, another exception occurred:

Traceback (most recent call last):
  File "C:\projects\lesson2\learn-homework-1\untitled\lib\site-packages\telegram\vendor\ptb_urllib3\urllib3\contrib\socks.py", line 88, in _new_conn
    **extra_kw
  File "C:\projects\lesson2\learn-homework-1\untitled\lib\site-packages\socks.py", line 209, in create_connection
    raise err
  File "C:\projects\lesson2\learn-homework-1\untitled\lib\site-packages\socks.py", line 199, in create_connection
    sock.connect((remote_host, remote_port))
  File "C:\projects\lesson2\learn-homework-1\untitled\lib\site-packages\socks.py", line 47, in wrapper
    return function(*args, **kwargs)
  File "C:\projects\lesson2\learn-homework-1\untitled\lib\site-packages\socks.py", line 814, in connect
    raise GeneralProxyError("Socket error", error)
socks.GeneralProxyError: Socket error: [Errno 11004] getaddrinfo failed

During handling of the above exception, another exception occurred:

Traceback (most recent call last):
  File "C:\projects\lesson2\learn-homework-1\untitled\lib\site-packages\telegram\vendor\ptb_urllib3\urllib3\connectionpool.py", line 617, in urlopen
    chunked=chunked)
  File "C:\projects\lesson2\learn-homework-1\untitled\lib\site-packages\telegram\vendor\ptb_urllib3\urllib3\connectionpool.py", line 360, in _make_request
    self._validate_conn(conn)
  File "C:\projects\lesson2\learn-homework-1\untitled\lib\site-packages\telegram\vendor\ptb_urllib3\urllib3\connectionpool.py", line 857, in _validate_conn
    super(HTTPSConnectionPool, self)._validate_conn(conn)
  File "C:\projects\lesson2\learn-homework-1\untitled\lib\site-packages\telegram\vendor\ptb_urllib3\urllib3\connectionpool.py", line 289, in _validate_conn
    conn.connect()
  File "C:\projects\lesson2\learn-homework-1\untitled\lib\site-packages\telegram\vendor\ptb_urllib3\urllib3\connection.py", line 284, in connect
    conn = self._new_conn()
  File "C:\projects\lesson2\learn-homework-1\untitled\lib\site-packages\telegram\vendor\ptb_urllib3\urllib3\contrib\socks.py", line 110, in _new_conn
    "Failed to establish a new connection: %s" % error
telegram.vendor.ptb_urllib3.urllib3.exceptions.NewConnectionError: <telegram.vendor.ptb_urllib3.urllib3.contrib.socks.SOCKSHTTPSConnection object at 0x000001FB670097F0>: Failed to establish a new connection: [Errno 11004] getaddrinfo failed

During handling of the above exception, another exception occurred:

Traceback (most recent call last):
  File "C:\projects\lesson2\learn-homework-1\untitled\lib\site-packages\telegram\utils\request.py", line 203, in _request_wrapper
    resp = self._con_pool.request(*args, **kwargs)
  File "C:\projects\lesson2\learn-homework-1\untitled\lib\site-packages\telegram\vendor\ptb_urllib3\urllib3\request.py", line 70, in request
    **urlopen_kw)
  File "C:\projects\lesson2\learn-homework-1\untitled\lib\site-packages\telegram\vendor\ptb_urllib3\urllib3\request.py", line 148, in request_encode_body
    return self.urlopen(method, url, **extra_kw)
  File "C:\projects\lesson2\learn-homework-1\untitled\lib\site-packages\telegram\vendor\ptb_urllib3\urllib3\poolmanager.py", line 244, in urlopen
    response = conn.urlopen(method, u.request_uri, **kw)
  File "C:\projects\lesson2\learn-homework-1\untitled\lib\site-packages\telegram\vendor\ptb_urllib3\urllib3\connectionpool.py", line 695, in urlopen
    **response_kw)
  File "C:\projects\lesson2\learn-homework-1\untitled\lib\site-packages\telegram\vendor\ptb_urllib3\urllib3\connectionpool.py", line 695, in urlopen
    **response_kw)
  File "C:\projects\lesson2\learn-homework-1\untitled\lib\site-packages\telegram\vendor\ptb_urllib3\urllib3\connectionpool.py", line 695, in urlopen
    **response_kw)
  File "C:\projects\lesson2\learn-homework-1\untitled\lib\site-packages\telegram\vendor\ptb_urllib3\urllib3\connectionpool.py", line 666, in urlopen
    _stacktrace=sys.exc_info()[2])
  File "C:\projects\lesson2\learn-homework-1\untitled\lib\site-packages\telegram\vendor\ptb_urllib3\urllib3\util\retry.py", line 376, in increment
    raise MaxRetryError(_pool, url, error or ResponseError(cause))
telegram.vendor.ptb_urllib3.urllib3.exceptions.MaxRetryError: SOCKSHTTPSConnectionPool(host='api.telegram.org', port=443): Max retries exceeded with url: /bot806287477:AAGRPsodiHUxnxz2zWZAUcUeUiTkIaqkMIo/getUpdates (Caused by NewConnectionError('<telegram.vendor.ptb_urllib3.urllib3.contrib.socks.SOCKSHTTPSConnection object at 0x000001FB670097F0>: Failed to establish a new connection: [Errno 11004] getaddrinfo failed',))

During handling of the above exception, another exception occurred:

Traceback (most recent call last):
  File "C:\projects\lesson2\learn-homework-1\untitled\lib\site-packages\telegram\ext\updater.py", line 319, in _network_loop_retry
    if not action_cb():
  File "C:\projects\lesson2\learn-homework-1\untitled\lib\site-packages\telegram\ext\updater.py", line 280, in polling_action_cb
    allowed_updates=allowed_updates)
  File "C:\projects\lesson2\learn-homework-1\untitled\lib\site-packages\telegram\bot.py", line 65, in decorator
    result = func(self, *args, **kwargs)
  File "C:\projects\lesson2\learn-homework-1\untitled\lib\site-packages\telegram\bot.py", line 1975, in get_updates
    result = self._request.post(url, data, timeout=float(read_latency) + float(timeout))
  File "C:\projects\lesson2\learn-homework-1\untitled\lib\site-packages\telegram\utils\request.py", line 309, in post
    headers={'Content-Type': 'application/json'})
  File "C:\projects\lesson2\learn-homework-1\untitled\lib\site-packages\telegram\utils\request.py", line 209, in _request_wrapper
    raise NetworkError('urllib3 HTTPError {0}'.format(error))
telegram.error.NetworkError: urllib3 HTTPError SOCKSHTTPSConnectionPool(host='api.telegram.org', port=443): Max retries exceeded with url: /bot806287477:AAGRPsodiHUxnxz2zWZAUcUeUiTkIaqkMIo/getUpdates (Caused by NewConnectionError('<telegram.vendor.ptb_urllib3.urllib3.contrib.socks.SOCKSHTTPSConnection object at 0x000001FB670097F0>: Failed to establish a new connection: [Errno 11004] getaddrinfo failed',))
telegram.vendor.ptb_urllib3.urllib3.connectionpool - WARNING - Retrying (Retry(total=2, connect=None, read=None, redirect=None)) after connection broken by 'NewConnectionError('<telegram.vendor.ptb_urllib3.urllib3.contrib.socks.SOCKSHTTPSConnection object at 0x000001FB6786DD68>: Failed to establish a new connection: [Errno 11001] getaddrinfo failed',)': /bot806287477:AAGRPsodiHUxnxz2zWZAUcUeUiTkIaqkMIo/getUpdates
telegram.vendor.ptb_urllib3.urllib3.connectionpool - WARNING - Retrying (Retry(total=1, connect=None, read=None, redirect=None)) after connection broken by 'NewConnectionError('<telegram.vendor.ptb_urllib3.urllib3.contrib.socks.SOCKSHTTPSConnection object at 0x000001FB6786D668>: Failed to establish a new connection: [Errno 11001] getaddrinfo failed',)': /bot806287477:AAGRPsodiHUxnxz2zWZAUcUeUiTkIaqkMIo/getUpdates
telegram.vendor.ptb_urllib3.urllib3.connectionpool - WARNING - Retrying (Retry(total=0, connect=None, read=None, redirect=None)) after connection broken by 'NewConnectionError('<telegram.vendor.ptb_urllib3.urllib3.contrib.socks.SOCKSHTTPSConnection object at 0x000001FB6786DE10>: Failed to establish a new connection: [Errno 11001] getaddrinfo failed',)': /bot806287477:AAGRPsodiHUxnxz2zWZAUcUeUiTkIaqkMIo/getUpdates
telegram.ext.updater - ERROR - Error while getting Updates: urllib3 HTTPError SOCKSHTTPSConnectionPool(host='api.telegram.org', port=443): Max retries exceeded with url: /bot806287477:AAGRPsodiHUxnxz2zWZAUcUeUiTkIaqkMIo/getUpdates (Caused by NewConnectionError('<telegram.vendor.ptb_urllib3.urllib3.contrib.socks.SOCKSHTTPSConnection object at 0x000001FB6786D748>: Failed to establish a new connection: [Errno 11001] getaddrinfo failed',))
telegram.ext.dispatcher - ERROR - No error handlers are registered, logging exception.
Traceback (most recent call last):
  File "C:\projects\lesson2\learn-homework-1\untitled\lib\site-packages\socks.py", line 809, in connect
    negotiate(self, dest_addr, dest_port)
  File "C:\projects\lesson2\learn-homework-1\untitled\lib\site-packages\socks.py", line 444, in _negotiate_SOCKS5
    self, CONNECT, dest_addr)
  File "C:\projects\lesson2\learn-homework-1\untitled\lib\site-packages\socks.py", line 520, in _SOCKS5_request
    resolved = self._write_SOCKS5_address(dst, writer)
  File "C:\projects\lesson2\learn-homework-1\untitled\lib\site-packages\socks.py", line 576, in _write_SOCKS5_address
    socket.AI_ADDRCONFIG)
  File "C:\Users\Anna\AppData\Local\Programs\Python\Python36\lib\socket.py", line 745, in getaddrinfo
    for res in _socket.getaddrinfo(host, port, family, type, proto, flags):
socket.gaierror: [Errno 11001] getaddrinfo failed

During handling of the above exception, another exception occurred:

Traceback (most recent call last):
  File "C:\projects\lesson2\learn-homework-1\untitled\lib\site-packages\telegram\vendor\ptb_urllib3\urllib3\contrib\socks.py", line 88, in _new_conn
    **extra_kw
  File "C:\projects\lesson2\learn-homework-1\untitled\lib\site-packages\socks.py", line 209, in create_connection
    raise err
  File "C:\projects\lesson2\learn-homework-1\untitled\lib\site-packages\socks.py", line 199, in create_connection
    sock.connect((remote_host, remote_port))
  File "C:\projects\lesson2\learn-homework-1\untitled\lib\site-packages\socks.py", line 47, in wrapper
    return function(*args, **kwargs)
  File "C:\projects\lesson2\learn-homework-1\untitled\lib\site-packages\socks.py", line 814, in connect
    raise GeneralProxyError("Socket error", error)
socks.GeneralProxyError: Socket error: [Errno 11001] getaddrinfo failed

During handling of the above exception, another exception occurred:

Traceback (most recent call last):
  File "C:\projects\lesson2\learn-homework-1\untitled\lib\site-packages\telegram\vendor\ptb_urllib3\urllib3\connectionpool.py", line 617, in urlopen
    chunked=chunked)
  File "C:\projects\lesson2\learn-homework-1\untitled\lib\site-packages\telegram\vendor\ptb_urllib3\urllib3\connectionpool.py", line 360, in _make_request
    self._validate_conn(conn)
  File "C:\projects\lesson2\learn-homework-1\untitled\lib\site-packages\telegram\vendor\ptb_urllib3\urllib3\connectionpool.py", line 857, in _validate_conn
    super(HTTPSConnectionPool, self)._validate_conn(conn)
  File "C:\projects\lesson2\learn-homework-1\untitled\lib\site-packages\telegram\vendor\ptb_urllib3\urllib3\connectionpool.py", line 289, in _validate_conn
    conn.connect()
  File "C:\projects\lesson2\learn-homework-1\untitled\lib\site-packages\telegram\vendor\ptb_urllib3\urllib3\connection.py", line 284, in connect
    conn = self._new_conn()
  File "C:\projects\lesson2\learn-homework-1\untitled\lib\site-packages\telegram\vendor\ptb_urllib3\urllib3\contrib\socks.py", line 110, in _new_conn
    "Failed to establish a new connection: %s" % error
telegram.vendor.ptb_urllib3.urllib3.exceptions.NewConnectionError: <telegram.vendor.ptb_urllib3.urllib3.contrib.socks.SOCKSHTTPSConnection object at 0x000001FB6786D748>: Failed to establish a new connection: [Errno 11001] getaddrinfo failed

During handling of the above exception, another exception occurred:

Traceback (most recent call last):
  File "C:\projects\lesson2\learn-homework-1\untitled\lib\site-packages\telegram\utils\request.py", line 203, in _request_wrapper
    resp = self._con_pool.request(*args, **kwargs)
  File "C:\projects\lesson2\learn-homework-1\untitled\lib\site-packages\telegram\vendor\ptb_urllib3\urllib3\request.py", line 70, in request
    **urlopen_kw)
  File "C:\projects\lesson2\learn-homework-1\untitled\lib\site-packages\telegram\vendor\ptb_urllib3\urllib3\request.py", line 148, in request_encode_body
    return self.urlopen(method, url, **extra_kw)
  File "C:\projects\lesson2\learn-homework-1\untitled\lib\site-packages\telegram\vendor\ptb_urllib3\urllib3\poolmanager.py", line 244, in urlopen
    response = conn.urlopen(method, u.request_uri, **kw)
  File "C:\projects\lesson2\learn-homework-1\untitled\lib\site-packages\telegram\vendor\ptb_urllib3\urllib3\connectionpool.py", line 695, in urlopen
    **response_kw)
  File "C:\projects\lesson2\learn-homework-1\untitled\lib\site-packages\telegram\vendor\ptb_urllib3\urllib3\connectionpool.py", line 695, in urlopen
    **response_kw)
  File "C:\projects\lesson2\learn-homework-1\untitled\lib\site-packages\telegram\vendor\ptb_urllib3\urllib3\connectionpool.py", line 695, in urlopen
    **response_kw)
  File "C:\projects\lesson2\learn-homework-1\untitled\lib\site-packages\telegram\vendor\ptb_urllib3\urllib3\connectionpool.py", line 666, in urlopen
    _stacktrace=sys.exc_info()[2])
  File "C:\projects\lesson2\learn-homework-1\untitled\lib\site-packages\telegram\vendor\ptb_urllib3\urllib3\util\retry.py", line 376, in increment
    raise MaxRetryError(_pool, url, error or ResponseError(cause))
telegram.vendor.ptb_urllib3.urllib3.exceptions.MaxRetryError: SOCKSHTTPSConnectionPool(host='api.telegram.org', port=443): Max retries exceeded with url: /bot806287477:AAGRPsodiHUxnxz2zWZAUcUeUiTkIaqkMIo/getUpdates (Caused by NewConnectionError('<telegram.vendor.ptb_urllib3.urllib3.contrib.socks.SOCKSHTTPSConnection object at 0x000001FB6786D748>: Failed to establish a new connection: [Errno 11001] getaddrinfo failed',))

During handling of the above exception, another exception occurred:

Traceback (most recent call last):
  File "C:\projects\lesson2\learn-homework-1\untitled\lib\site-packages\telegram\ext\updater.py", line 319, in _network_loop_retry
    if not action_cb():
  File "C:\projects\lesson2\learn-homework-1\untitled\lib\site-packages\telegram\ext\updater.py", line 280, in polling_action_cb
    allowed_updates=allowed_updates)
  File "C:\projects\lesson2\learn-homework-1\untitled\lib\site-packages\telegram\bot.py", line 65, in decorator
    result = func(self, *args, **kwargs)
  File "C:\projects\lesson2\learn-homework-1\untitled\lib\site-packages\telegram\bot.py", line 1975, in get_updates
    result = self._request.post(url, data, timeout=float(read_latency) + float(timeout))
  File "C:\projects\lesson2\learn-homework-1\untitled\lib\site-packages\telegram\utils\request.py", line 309, in post
    headers={'Content-Type': 'application/json'})
  File "C:\projects\lesson2\learn-homework-1\untitled\lib\site-packages\telegram\utils\request.py", line 209, in _request_wrapper
    raise NetworkError('urllib3 HTTPError {0}'.format(error))
telegram.error.NetworkError: urllib3 HTTPError SOCKSHTTPSConnectionPool(host='api.telegram.org', port=443): Max retries exceeded with url: /bot806287477:AAGRPsodiHUxnxz2zWZAUcUeUiTkIaqkMIo/getUpdates (Caused by NewConnectionError('<telegram.vendor.ptb_urllib3.urllib3.contrib.socks.SOCKSHTTPSConnection object at 0x000001FB6786D748>: Failed to establish a new connection: [Errno 11001] getaddrinfo failed',))
telegram.vendor.ptb_urllib3.urllib3.connectionpool - WARNING - Retrying (Retry(total=2, connect=None, read=None, redirect=None)) after connection broken by 'ConnectTimeoutError(<telegram.vendor.ptb_urllib3.urllib3.contrib.socks.SOCKSHTTPSConnection object at 0x000001FB67029860>, 'Connection to api.telegram.org timed out. (connect timeout=5.0)')': /bot806287477:AAGRPsodiHUxnxz2zWZAUcUeUiTkIaqkMIo/getUpdates
telegram.vendor.ptb_urllib3.urllib3.connectionpool - WARNING - Retrying (Retry(total=1, connect=None, read=None, redirect=None)) after connection broken by 'NewConnectionError('<telegram.vendor.ptb_urllib3.urllib3.contrib.socks.SOCKSHTTPSConnection object at 0x000001FB67029EB8>: Failed to establish a new connection: [Errno 11001] getaddrinfo failed',)': /bot806287477:AAGRPsodiHUxnxz2zWZAUcUeUiTkIaqkMIo/getUpdates
telegram.vendor.ptb_urllib3.urllib3.connectionpool - WARNING - Retrying (Retry(total=0, connect=None, read=None, redirect=None)) after connection broken by 'NewConnectionError('<telegram.vendor.ptb_urllib3.urllib3.contrib.socks.SOCKSHTTPSConnection object at 0x000001FB67029550>: Failed to establish a new connection: [Errno 11001] getaddrinfo failed',)': /bot806287477:AAGRPsodiHUxnxz2zWZAUcUeUiTkIaqkMIo/getUpdates
telegram.ext.updater - ERROR - Error while getting Updates: urllib3 HTTPError SOCKSHTTPSConnectionPool(host='api.telegram.org', port=443): Max retries exceeded with url: /bot806287477:AAGRPsodiHUxnxz2zWZAUcUeUiTkIaqkMIo/getUpdates (Caused by NewConnectionError('<telegram.vendor.ptb_urllib3.urllib3.contrib.socks.SOCKSHTTPSConnection object at 0x000001FB67029630>: Failed to establish a new connection: [Errno 11001] getaddrinfo failed',))
telegram.ext.dispatcher - ERROR - No error handlers are registered, logging exception.
Traceback (most recent call last):
  File "C:\projects\lesson2\learn-homework-1\untitled\lib\site-packages\telegram\vendor\ptb_urllib3\urllib3\contrib\socks.py", line 88, in _new_conn
    **extra_kw
  File "C:\projects\lesson2\learn-homework-1\untitled\lib\site-packages\socks.py", line 180, in create_connection
    for r in socket.getaddrinfo(proxy_addr, proxy_port, 0, socket.SOCK_STREAM):
  File "C:\Users\Anna\AppData\Local\Programs\Python\Python36\lib\socket.py", line 745, in getaddrinfo
    for res in _socket.getaddrinfo(host, port, family, type, proto, flags):
socket.gaierror: [Errno 11001] getaddrinfo failed

During handling of the above exception, another exception occurred:

Traceback (most recent call last):
  File "C:\projects\lesson2\learn-homework-1\untitled\lib\site-packages\telegram\vendor\ptb_urllib3\urllib3\connectionpool.py", line 617, in urlopen
    chunked=chunked)
  File "C:\projects\lesson2\learn-homework-1\untitled\lib\site-packages\telegram\vendor\ptb_urllib3\urllib3\connectionpool.py", line 360, in _make_request
    self._validate_conn(conn)
  File "C:\projects\lesson2\learn-homework-1\untitled\lib\site-packages\telegram\vendor\ptb_urllib3\urllib3\connectionpool.py", line 857, in _validate_conn
    super(HTTPSConnectionPool, self)._validate_conn(conn)
  File "C:\projects\lesson2\learn-homework-1\untitled\lib\site-packages\telegram\vendor\ptb_urllib3\urllib3\connectionpool.py", line 289, in _validate_conn
    conn.connect()
  File "C:\projects\lesson2\learn-homework-1\untitled\lib\site-packages\telegram\vendor\ptb_urllib3\urllib3\connection.py", line 284, in connect
    conn = self._new_conn()
  File "C:\projects\lesson2\learn-homework-1\untitled\lib\site-packages\telegram\vendor\ptb_urllib3\urllib3\contrib\socks.py", line 120, in _new_conn
    self, "Failed to establish a new connection: %s" % e)
telegram.vendor.ptb_urllib3.urllib3.exceptions.NewConnectionError: <telegram.vendor.ptb_urllib3.urllib3.contrib.socks.SOCKSHTTPSConnection object at 0x000001FB67029630>: Failed to establish a new connection: [Errno 11001] getaddrinfo failed

During handling of the above exception, another exception occurred:

Traceback (most recent call last):
  File "C:\projects\lesson2\learn-homework-1\untitled\lib\site-packages\telegram\utils\request.py", line 203, in _request_wrapper
    resp = self._con_pool.request(*args, **kwargs)
  File "C:\projects\lesson2\learn-homework-1\untitled\lib\site-packages\telegram\vendor\ptb_urllib3\urllib3\request.py", line 70, in request
    **urlopen_kw)
  File "C:\projects\lesson2\learn-homework-1\untitled\lib\site-packages\telegram\vendor\ptb_urllib3\urllib3\request.py", line 148, in request_encode_body
    return self.urlopen(method, url, **extra_kw)
  File "C:\projects\lesson2\learn-homework-1\untitled\lib\site-packages\telegram\vendor\ptb_urllib3\urllib3\poolmanager.py", line 244, in urlopen
    response = conn.urlopen(method, u.request_uri, **kw)
  File "C:\projects\lesson2\learn-homework-1\untitled\lib\site-packages\telegram\vendor\ptb_urllib3\urllib3\connectionpool.py", line 695, in urlopen
    **response_kw)
  File "C:\projects\lesson2\learn-homework-1\untitled\lib\site-packages\telegram\vendor\ptb_urllib3\urllib3\connectionpool.py", line 695, in urlopen
    **response_kw)
  File "C:\projects\lesson2\learn-homework-1\untitled\lib\site-packages\telegram\vendor\ptb_urllib3\urllib3\connectionpool.py", line 695, in urlopen
    **response_kw)
  File "C:\projects\lesson2\learn-homework-1\untitled\lib\site-packages\telegram\vendor\ptb_urllib3\urllib3\connectionpool.py", line 666, in urlopen
    _stacktrace=sys.exc_info()[2])
  File "C:\projects\lesson2\learn-homework-1\untitled\lib\site-packages\telegram\vendor\ptb_urllib3\urllib3\util\retry.py", line 376, in increment
    raise MaxRetryError(_pool, url, error or ResponseError(cause))
telegram.vendor.ptb_urllib3.urllib3.exceptions.MaxRetryError: SOCKSHTTPSConnectionPool(host='api.telegram.org', port=443): Max retries exceeded with url: /bot806287477:AAGRPsodiHUxnxz2zWZAUcUeUiTkIaqkMIo/getUpdates (Caused by NewConnectionError('<telegram.vendor.ptb_urllib3.urllib3.contrib.socks.SOCKSHTTPSConnection object at 0x000001FB67029630>: Failed to establish a new connection: [Errno 11001] getaddrinfo failed',))

During handling of the above exception, another exception occurred:

Traceback (most recent call last):
  File "C:\projects\lesson2\learn-homework-1\untitled\lib\site-packages\telegram\ext\updater.py", line 319, in _network_loop_retry
    if not action_cb():
  File "C:\projects\lesson2\learn-homework-1\untitled\lib\site-packages\telegram\ext\updater.py", line 280, in polling_action_cb
    allowed_updates=allowed_updates)
  File "C:\projects\lesson2\learn-homework-1\untitled\lib\site-packages\telegram\bot.py", line 65, in decorator
    result = func(self, *args, **kwargs)
  File "C:\projects\lesson2\learn-homework-1\untitled\lib\site-packages\telegram\bot.py", line 1975, in get_updates
    result = self._request.post(url, data, timeout=float(read_latency) + float(timeout))
  File "C:\projects\lesson2\learn-homework-1\untitled\lib\site-packages\telegram\utils\request.py", line 309, in post
    headers={'Content-Type': 'application/json'})
  File "C:\projects\lesson2\learn-homework-1\untitled\lib\site-packages\telegram\utils\request.py", line 209, in _request_wrapper
    raise NetworkError('urllib3 HTTPError {0}'.format(error))
telegram.error.NetworkError: urllib3 HTTPError SOCKSHTTPSConnectionPool(host='api.telegram.org', port=443): Max retries exceeded with url: /bot806287477:AAGRPsodiHUxnxz2zWZAUcUeUiTkIaqkMIo/getUpdates (Caused by NewConnectionError('<telegram.vendor.ptb_urllib3.urllib3.contrib.socks.SOCKSHTTPSConnection object at 0x000001FB67029630>: Failed to establish a new connection: [Errno 11001] getaddrinfo failed',))
telegram.vendor.ptb_urllib3.urllib3.connectionpool - WARNING - Retrying (Retry(total=2, connect=None, read=None, redirect=None)) after connection broken by 'NewConnectionError('<telegram.vendor.ptb_urllib3.urllib3.contrib.socks.SOCKSHTTPSConnection object at 0x000001FB67029710>: Failed to establish a new connection: [Errno 11001] getaddrinfo failed',)': /bot806287477:AAGRPsodiHUxnxz2zWZAUcUeUiTkIaqkMIo/getUpdates
telegram.vendor.ptb_urllib3.urllib3.connectionpool - WARNING - Retrying (Retry(total=1, connect=None, read=None, redirect=None)) after connection broken by 'NewConnectionError('<telegram.vendor.ptb_urllib3.urllib3.contrib.socks.SOCKSHTTPSConnection object at 0x000001FB68A49DD8>: Failed to establish a new connection: [Errno 11001] getaddrinfo failed',)': /bot806287477:AAGRPsodiHUxnxz2zWZAUcUeUiTkIaqkMIo/getUpdates
telegram.vendor.ptb_urllib3.urllib3.connectionpool - WARNING - Retrying (Retry(total=0, connect=None, read=None, redirect=None)) after connection broken by 'NewConnectionError('<telegram.vendor.ptb_urllib3.urllib3.contrib.socks.SOCKSHTTPSConnection object at 0x000001FB68A49E10>: Failed to establish a new connection: [Errno 11001] getaddrinfo failed',)': /bot806287477:AAGRPsodiHUxnxz2zWZAUcUeUiTkIaqkMIo/getUpdates
telegram.ext.updater - ERROR - Error while getting Updates: urllib3 HTTPError SOCKSHTTPSConnectionPool(host='api.telegram.org', port=443): Max retries exceeded with url: /bot806287477:AAGRPsodiHUxnxz2zWZAUcUeUiTkIaqkMIo/getUpdates (Caused by NewConnectionError('<telegram.vendor.ptb_urllib3.urllib3.contrib.socks.SOCKSHTTPSConnection object at 0x000001FB67843C18>: Failed to establish a new connection: [Errno 11001] getaddrinfo failed',))
telegram.ext.dispatcher - ERROR - No error handlers are registered, logging exception.
Traceback (most recent call last):
  File "C:\projects\lesson2\learn-homework-1\untitled\lib\site-packages\telegram\vendor\ptb_urllib3\urllib3\contrib\socks.py", line 88, in _new_conn
    **extra_kw
  File "C:\projects\lesson2\learn-homework-1\untitled\lib\site-packages\socks.py", line 180, in create_connection
    for r in socket.getaddrinfo(proxy_addr, proxy_port, 0, socket.SOCK_STREAM):
  File "C:\Users\Anna\AppData\Local\Programs\Python\Python36\lib\socket.py", line 745, in getaddrinfo
    for res in _socket.getaddrinfo(host, port, family, type, proto, flags):
socket.gaierror: [Errno 11001] getaddrinfo failed

During handling of the above exception, another exception occurred:

Traceback (most recent call last):
  File "C:\projects\lesson2\learn-homework-1\untitled\lib\site-packages\telegram\vendor\ptb_urllib3\urllib3\connectionpool.py", line 617, in urlopen
    chunked=chunked)
  File "C:\projects\lesson2\learn-homework-1\untitled\lib\site-packages\telegram\vendor\ptb_urllib3\urllib3\connectionpool.py", line 360, in _make_request
    self._validate_conn(conn)
  File "C:\projects\lesson2\learn-homework-1\untitled\lib\site-packages\telegram\vendor\ptb_urllib3\urllib3\connectionpool.py", line 857, in _validate_conn
    super(HTTPSConnectionPool, self)._validate_conn(conn)
  File "C:\projects\lesson2\learn-homework-1\untitled\lib\site-packages\telegram\vendor\ptb_urllib3\urllib3\connectionpool.py", line 289, in _validate_conn
    conn.connect()
  File "C:\projects\lesson2\learn-homework-1\untitled\lib\site-packages\telegram\vendor\ptb_urllib3\urllib3\connection.py", line 284, in connect
    conn = self._new_conn()
  File "C:\projects\lesson2\learn-homework-1\untitled\lib\site-packages\telegram\vendor\ptb_urllib3\urllib3\contrib\socks.py", line 120, in _new_conn
    self, "Failed to establish a new connection: %s" % e)
telegram.vendor.ptb_urllib3.urllib3.exceptions.NewConnectionError: <telegram.vendor.ptb_urllib3.urllib3.contrib.socks.SOCKSHTTPSConnection object at 0x000001FB67843C18>: Failed to establish a new connection: [Errno 11001] getaddrinfo failed

During handling of the above exception, another exception occurred:

Traceback (most recent call last):
  File "C:\projects\lesson2\learn-homework-1\untitled\lib\site-packages\telegram\utils\request.py", line 203, in _request_wrapper
    resp = self._con_pool.request(*args, **kwargs)
  File "C:\projects\lesson2\learn-homework-1\untitled\lib\site-packages\telegram\vendor\ptb_urllib3\urllib3\request.py", line 70, in request
    **urlopen_kw)
  File "C:\projects\lesson2\learn-homework-1\untitled\lib\site-packages\telegram\vendor\ptb_urllib3\urllib3\request.py", line 148, in request_encode_body
    return self.urlopen(method, url, **extra_kw)
  File "C:\projects\lesson2\learn-homework-1\untitled\lib\site-packages\telegram\vendor\ptb_urllib3\urllib3\poolmanager.py", line 244, in urlopen
    response = conn.urlopen(method, u.request_uri, **kw)
  File "C:\projects\lesson2\learn-homework-1\untitled\lib\site-packages\telegram\vendor\ptb_urllib3\urllib3\connectionpool.py", line 695, in urlopen
    **response_kw)
  File "C:\projects\lesson2\learn-homework-1\untitled\lib\site-packages\telegram\vendor\ptb_urllib3\urllib3\connectionpool.py", line 695, in urlopen
    **response_kw)
  File "C:\projects\lesson2\learn-homework-1\untitled\lib\site-packages\telegram\vendor\ptb_urllib3\urllib3\connectionpool.py", line 695, in urlopen
    **response_kw)
  File "C:\projects\lesson2\learn-homework-1\untitled\lib\site-packages\telegram\vendor\ptb_urllib3\urllib3\connectionpool.py", line 666, in urlopen
    _stacktrace=sys.exc_info()[2])
  File "C:\projects\lesson2\learn-homework-1\untitled\lib\site-packages\telegram\vendor\ptb_urllib3\urllib3\util\retry.py", line 376, in increment
    raise MaxRetryError(_pool, url, error or ResponseError(cause))
telegram.vendor.ptb_urllib3.urllib3.exceptions.MaxRetryError: SOCKSHTTPSConnectionPool(host='api.telegram.org', port=443): Max retries exceeded with url: /bot806287477:AAGRPsodiHUxnxz2zWZAUcUeUiTkIaqkMIo/getUpdates (Caused by NewConnectionError('<telegram.vendor.ptb_urllib3.urllib3.contrib.socks.SOCKSHTTPSConnection object at 0x000001FB67843C18>: Failed to establish a new connection: [Errno 11001] getaddrinfo failed',))

During handling of the above exception, another exception occurred:

Traceback (most recent call last):
  File "C:\projects\lesson2\learn-homework-1\untitled\lib\site-packages\telegram\ext\updater.py", line 319, in _network_loop_retry
    if not action_cb():
  File "C:\projects\lesson2\learn-homework-1\untitled\lib\site-packages\telegram\ext\updater.py", line 280, in polling_action_cb
    allowed_updates=allowed_updates)
  File "C:\projects\lesson2\learn-homework-1\untitled\lib\site-packages\telegram\bot.py", line 65, in decorator
    result = func(self, *args, **kwargs)
  File "C:\projects\lesson2\learn-homework-1\untitled\lib\site-packages\telegram\bot.py", line 1975, in get_updates
    result = self._request.post(url, data, timeout=float(read_latency) + float(timeout))
  File "C:\projects\lesson2\learn-homework-1\untitled\lib\site-packages\telegram\utils\request.py", line 309, in post
    headers={'Content-Type': 'application/json'})
  File "C:\projects\lesson2\learn-homework-1\untitled\lib\site-packages\telegram\utils\request.py", line 209, in _request_wrapper
    raise NetworkError('urllib3 HTTPError {0}'.format(error))
telegram.error.NetworkError: urllib3 HTTPError SOCKSHTTPSConnectionPool(host='api.telegram.org', port=443): Max retries exceeded with url: /bot806287477:AAGRPsodiHUxnxz2zWZAUcUeUiTkIaqkMIo/getUpdates (Caused by NewConnectionError('<telegram.vendor.ptb_urllib3.urllib3.contrib.socks.SOCKSHTTPSConnection object at 0x000001FB67843C18>: Failed to establish a new connection: [Errno 11001] getaddrinfo failed',))
telegram.vendor.ptb_urllib3.urllib3.connectionpool - WARNING - Retrying (Retry(total=2, connect=None, read=None, redirect=None)) after connection broken by 'NewConnectionError('<telegram.vendor.ptb_urllib3.urllib3.contrib.socks.SOCKSHTTPSConnection object at 0x000001FB67843E80>: Failed to establish a new connection: [Errno 11001] getaddrinfo failed',)': /bot806287477:AAGRPsodiHUxnxz2zWZAUcUeUiTkIaqkMIo/getUpdates
telegram.vendor.ptb_urllib3.urllib3.connectionpool - WARNING - Retrying (Retry(total=1, connect=None, read=None, redirect=None)) after connection broken by 'NewConnectionError('<telegram.vendor.ptb_urllib3.urllib3.contrib.socks.SOCKSHTTPSConnection object at 0x000001FB67843B38>: Failed to establish a new connection: [Errno 11001] getaddrinfo failed',)': /bot806287477:AAGRPsodiHUxnxz2zWZAUcUeUiTkIaqkMIo/getUpdates
telegram.vendor.ptb_urllib3.urllib3.connectionpool - WARNING - Retrying (Retry(total=0, connect=None, read=None, redirect=None)) after connection broken by 'NewConnectionError('<telegram.vendor.ptb_urllib3.urllib3.contrib.socks.SOCKSHTTPSConnection object at 0x000001FB67843400>: Failed to establish a new connection: [Errno 11001] getaddrinfo failed',)': /bot806287477:AAGRPsodiHUxnxz2zWZAUcUeUiTkIaqkMIo/getUpdates
telegram.ext.updater - ERROR - Error while getting Updates: urllib3 HTTPError SOCKSHTTPSConnectionPool(host='api.telegram.org', port=443): Max retries exceeded with url: /bot806287477:AAGRPsodiHUxnxz2zWZAUcUeUiTkIaqkMIo/getUpdates (Caused by NewConnectionError('<telegram.vendor.ptb_urllib3.urllib3.contrib.socks.SOCKSHTTPSConnection object at 0x000001FB67029400>: Failed to establish a new connection: [Errno 11001] getaddrinfo failed',))
telegram.ext.dispatcher - ERROR - No error handlers are registered, logging exception.
Traceback (most recent call last):
  File "C:\projects\lesson2\learn-homework-1\untitled\lib\site-packages\telegram\vendor\ptb_urllib3\urllib3\contrib\socks.py", line 88, in _new_conn
    **extra_kw
  File "C:\projects\lesson2\learn-homework-1\untitled\lib\site-packages\socks.py", line 180, in create_connection
    for r in socket.getaddrinfo(proxy_addr, proxy_port, 0, socket.SOCK_STREAM):
  File "C:\Users\Anna\AppData\Local\Programs\Python\Python36\lib\socket.py", line 745, in getaddrinfo
    for res in _socket.getaddrinfo(host, port, family, type, proto, flags):
socket.gaierror: [Errno 11001] getaddrinfo failed

During handling of the above exception, another exception occurred:

Traceback (most recent call last):
  File "C:\projects\lesson2\learn-homework-1\untitled\lib\site-packages\telegram\vendor\ptb_urllib3\urllib3\connectionpool.py", line 617, in urlopen
    chunked=chunked)
  File "C:\projects\lesson2\learn-homework-1\untitled\lib\site-packages\telegram\vendor\ptb_urllib3\urllib3\connectionpool.py", line 360, in _make_request
    self._validate_conn(conn)
  File "C:\projects\lesson2\learn-homework-1\untitled\lib\site-packages\telegram\vendor\ptb_urllib3\urllib3\connectionpool.py", line 857, in _validate_conn
    super(HTTPSConnectionPool, self)._validate_conn(conn)
  File "C:\projects\lesson2\learn-homework-1\untitled\lib\site-packages\telegram\vendor\ptb_urllib3\urllib3\connectionpool.py", line 289, in _validate_conn
    conn.connect()
  File "C:\projects\lesson2\learn-homework-1\untitled\lib\site-packages\telegram\vendor\ptb_urllib3\urllib3\connection.py", line 284, in connect
    conn = self._new_conn()
  File "C:\projects\lesson2\learn-homework-1\untitled\lib\site-packages\telegram\vendor\ptb_urllib3\urllib3\contrib\socks.py", line 120, in _new_conn
    self, "Failed to establish a new connection: %s" % e)
telegram.vendor.ptb_urllib3.urllib3.exceptions.NewConnectionError: <telegram.vendor.ptb_urllib3.urllib3.contrib.socks.SOCKSHTTPSConnection object at 0x000001FB67029400>: Failed to establish a new connection: [Errno 11001] getaddrinfo failed

During handling of the above exception, another exception occurred:

Traceback (most recent call last):
  File "C:\projects\lesson2\learn-homework-1\untitled\lib\site-packages\telegram\utils\request.py", line 203, in _request_wrapper
    resp = self._con_pool.request(*args, **kwargs)
  File "C:\projects\lesson2\learn-homework-1\untitled\lib\site-packages\telegram\vendor\ptb_urllib3\urllib3\request.py", line 70, in request
    **urlopen_kw)
  File "C:\projects\lesson2\learn-homework-1\untitled\lib\site-packages\telegram\vendor\ptb_urllib3\urllib3\request.py", line 148, in request_encode_body
    return self.urlopen(method, url, **extra_kw)
  File "C:\projects\lesson2\learn-homework-1\untitled\lib\site-packages\telegram\vendor\ptb_urllib3\urllib3\poolmanager.py", line 244, in urlopen
    response = conn.urlopen(method, u.request_uri, **kw)
  File "C:\projects\lesson2\learn-homework-1\untitled\lib\site-packages\telegram\vendor\ptb_urllib3\urllib3\connectionpool.py", line 695, in urlopen
    **response_kw)
  File "C:\projects\lesson2\learn-homework-1\untitled\lib\site-packages\telegram\vendor\ptb_urllib3\urllib3\connectionpool.py", line 695, in urlopen
    **response_kw)
  File "C:\projects\lesson2\learn-homework-1\untitled\lib\site-packages\telegram\vendor\ptb_urllib3\urllib3\connectionpool.py", line 695, in urlopen
    **response_kw)
  File "C:\projects\lesson2\learn-homework-1\untitled\lib\site-packages\telegram\vendor\ptb_urllib3\urllib3\connectionpool.py", line 666, in urlopen
    _stacktrace=sys.exc_info()[2])
  File "C:\projects\lesson2\learn-homework-1\untitled\lib\site-packages\telegram\vendor\ptb_urllib3\urllib3\util\retry.py", line 376, in increment
    raise MaxRetryError(_pool, url, error or ResponseError(cause))
telegram.vendor.ptb_urllib3.urllib3.exceptions.MaxRetryError: SOCKSHTTPSConnectionPool(host='api.telegram.org', port=443): Max retries exceeded with url: /bot806287477:AAGRPsodiHUxnxz2zWZAUcUeUiTkIaqkMIo/getUpdates (Caused by NewConnectionError('<telegram.vendor.ptb_urllib3.urllib3.contrib.socks.SOCKSHTTPSConnection object at 0x000001FB67029400>: Failed to establish a new connection: [Errno 11001] getaddrinfo failed',))

During handling of the above exception, another exception occurred:

Traceback (most recent call last):
  File "C:\projects\lesson2\learn-homework-1\untitled\lib\site-packages\telegram\ext\updater.py", line 319, in _network_loop_retry
    if not action_cb():
  File "C:\projects\lesson2\learn-homework-1\untitled\lib\site-packages\telegram\ext\updater.py", line 280, in polling_action_cb
    allowed_updates=allowed_updates)
  File "C:\projects\lesson2\learn-homework-1\untitled\lib\site-packages\telegram\bot.py", line 65, in decorator
    result = func(self, *args, **kwargs)
  File "C:\projects\lesson2\learn-homework-1\untitled\lib\site-packages\telegram\bot.py", line 1975, in get_updates
    result = self._request.post(url, data, timeout=float(read_latency) + float(timeout))
  File "C:\projects\lesson2\learn-homework-1\untitled\lib\site-packages\telegram\utils\request.py", line 309, in post
    headers={'Content-Type': 'application/json'})
  File "C:\projects\lesson2\learn-homework-1\untitled\lib\site-packages\telegram\utils\request.py", line 209, in _request_wrapper
    raise NetworkError('urllib3 HTTPError {0}'.format(error))
telegram.error.NetworkError: urllib3 HTTPError SOCKSHTTPSConnectionPool(host='api.telegram.org', port=443): Max retries exceeded with url: /bot806287477:AAGRPsodiHUxnxz2zWZAUcUeUiTkIaqkMIo/getUpdates (Caused by NewConnectionError('<telegram.vendor.ptb_urllib3.urllib3.contrib.socks.SOCKSHTTPSConnection object at 0x000001FB67029400>: Failed to establish a new connection: [Errno 11001] getaddrinfo failed',))
telegram.vendor.ptb_urllib3.urllib3.connectionpool - WARNING - Retrying (Retry(total=2, connect=None, read=None, redirect=None)) after connection broken by 'NewConnectionError('<telegram.vendor.ptb_urllib3.urllib3.contrib.socks.SOCKSHTTPSConnection object at 0x000001FB67029080>: Failed to establish a new connection: [Errno 11001] getaddrinfo failed',)': /bot806287477:AAGRPsodiHUxnxz2zWZAUcUeUiTkIaqkMIo/getUpdates
telegram.vendor.ptb_urllib3.urllib3.connectionpool - WARNING - Retrying (Retry(total=1, connect=None, read=None, redirect=None)) after connection broken by 'NewConnectionError('<telegram.vendor.ptb_urllib3.urllib3.contrib.socks.SOCKSHTTPSConnection object at 0x000001FB67029748>: Failed to establish a new connection: [Errno 11001] getaddrinfo failed',)': /bot806287477:AAGRPsodiHUxnxz2zWZAUcUeUiTkIaqkMIo/getUpdates
telegram.vendor.ptb_urllib3.urllib3.connectionpool - WARNING - Retrying (Retry(total=0, connect=None, read=None, redirect=None)) after connection broken by 'NewConnectionError('<telegram.vendor.ptb_urllib3.urllib3.contrib.socks.SOCKSHTTPSConnection object at 0x000001FB67029128>: Failed to establish a new connection: [Errno 11001] getaddrinfo failed',)': /bot806287477:AAGRPsodiHUxnxz2zWZAUcUeUiTkIaqkMIo/getUpdates
telegram.ext.updater - ERROR - Error while getting Updates: urllib3 HTTPError SOCKSHTTPSConnectionPool(host='api.telegram.org', port=443): Max retries exceeded with url: /bot806287477:AAGRPsodiHUxnxz2zWZAUcUeUiTkIaqkMIo/getUpdates (Caused by NewConnectionError('<telegram.vendor.ptb_urllib3.urllib3.contrib.socks.SOCKSHTTPSConnection object at 0x000001FB66809E80>: Failed to establish a new connection: [Errno 11001] getaddrinfo failed',))
telegram.ext.dispatcher - ERROR - No error handlers are registered, logging exception.
Traceback (most recent call last):
  File "C:\projects\lesson2\learn-homework-1\untitled\lib\site-packages\telegram\vendor\ptb_urllib3\urllib3\contrib\socks.py", line 88, in _new_conn
    **extra_kw
  File "C:\projects\lesson2\learn-homework-1\untitled\lib\site-packages\socks.py", line 180, in create_connection
    for r in socket.getaddrinfo(proxy_addr, proxy_port, 0, socket.SOCK_STREAM):
  File "C:\Users\Anna\AppData\Local\Programs\Python\Python36\lib\socket.py", line 745, in getaddrinfo
    for res in _socket.getaddrinfo(host, port, family, type, proto, flags):
socket.gaierror: [Errno 11001] getaddrinfo failed

During handling of the above exception, another exception occurred:

Traceback (most recent call last):
  File "C:\projects\lesson2\learn-homework-1\untitled\lib\site-packages\telegram\vendor\ptb_urllib3\urllib3\connectionpool.py", line 617, in urlopen
    chunked=chunked)
  File "C:\projects\lesson2\learn-homework-1\untitled\lib\site-packages\telegram\vendor\ptb_urllib3\urllib3\connectionpool.py", line 360, in _make_request
    self._validate_conn(conn)
  File "C:\projects\lesson2\learn-homework-1\untitled\lib\site-packages\telegram\vendor\ptb_urllib3\urllib3\connectionpool.py", line 857, in _validate_conn
    super(HTTPSConnectionPool, self)._validate_conn(conn)
  File "C:\projects\lesson2\learn-homework-1\untitled\lib\site-packages\telegram\vendor\ptb_urllib3\urllib3\connectionpool.py", line 289, in _validate_conn
    conn.connect()
  File "C:\projects\lesson2\learn-homework-1\untitled\lib\site-packages\telegram\vendor\ptb_urllib3\urllib3\connection.py", line 284, in connect
    conn = self._new_conn()
  File "C:\projects\lesson2\learn-homework-1\untitled\lib\site-packages\telegram\vendor\ptb_urllib3\urllib3\contrib\socks.py", line 120, in _new_conn
    self, "Failed to establish a new connection: %s" % e)
telegram.vendor.ptb_urllib3.urllib3.exceptions.NewConnectionError: <telegram.vendor.ptb_urllib3.urllib3.contrib.socks.SOCKSHTTPSConnection object at 0x000001FB66809E80>: Failed to establish a new connection: [Errno 11001] getaddrinfo failed

During handling of the above exception, another exception occurred:

Traceback (most recent call last):
  File "C:\projects\lesson2\learn-homework-1\untitled\lib\site-packages\telegram\utils\request.py", line 203, in _request_wrapper
    resp = self._con_pool.request(*args, **kwargs)
  File "C:\projects\lesson2\learn-homework-1\untitled\lib\site-packages\telegram\vendor\ptb_urllib3\urllib3\request.py", line 70, in request
    **urlopen_kw)
  File "C:\projects\lesson2\learn-homework-1\untitled\lib\site-packages\telegram\vendor\ptb_urllib3\urllib3\request.py", line 148, in request_encode_body
    return self.urlopen(method, url, **extra_kw)
  File "C:\projects\lesson2\learn-homework-1\untitled\lib\site-packages\telegram\vendor\ptb_urllib3\urllib3\poolmanager.py", line 244, in urlopen
    response = conn.urlopen(method, u.request_uri, **kw)
  File "C:\projects\lesson2\learn-homework-1\untitled\lib\site-packages\telegram\vendor\ptb_urllib3\urllib3\connectionpool.py", line 695, in urlopen
    **response_kw)
  File "C:\projects\lesson2\learn-homework-1\untitled\lib\site-packages\telegram\vendor\ptb_urllib3\urllib3\connectionpool.py", line 695, in urlopen
    **response_kw)
  File "C:\projects\lesson2\learn-homework-1\untitled\lib\site-packages\telegram\vendor\ptb_urllib3\urllib3\connectionpool.py", line 695, in urlopen
    **response_kw)
  File "C:\projects\lesson2\learn-homework-1\untitled\lib\site-packages\telegram\vendor\ptb_urllib3\urllib3\connectionpool.py", line 666, in urlopen
    _stacktrace=sys.exc_info()[2])
  File "C:\projects\lesson2\learn-homework-1\untitled\lib\site-packages\telegram\vendor\ptb_urllib3\urllib3\util\retry.py", line 376, in increment
    raise MaxRetryError(_pool, url, error or ResponseError(cause))
telegram.vendor.ptb_urllib3.urllib3.exceptions.MaxRetryError: SOCKSHTTPSConnectionPool(host='api.telegram.org', port=443): Max retries exceeded with url: /bot806287477:AAGRPsodiHUxnxz2zWZAUcUeUiTkIaqkMIo/getUpdates (Caused by NewConnectionError('<telegram.vendor.ptb_urllib3.urllib3.contrib.socks.SOCKSHTTPSConnection object at 0x000001FB66809E80>: Failed to establish a new connection: [Errno 11001] getaddrinfo failed',))

During handling of the above exception, another exception occurred:

Traceback (most recent call last):
  File "C:\projects\lesson2\learn-homework-1\untitled\lib\site-packages\telegram\ext\updater.py", line 319, in _network_loop_retry
    if not action_cb():
  File "C:\projects\lesson2\learn-homework-1\untitled\lib\site-packages\telegram\ext\updater.py", line 280, in polling_action_cb
    allowed_updates=allowed_updates)
  File "C:\projects\lesson2\learn-homework-1\untitled\lib\site-packages\telegram\bot.py", line 65, in decorator
    result = func(self, *args, **kwargs)
  File "C:\projects\lesson2\learn-homework-1\untitled\lib\site-packages\telegram\bot.py", line 1975, in get_updates
    result = self._request.post(url, data, timeout=float(read_latency) + float(timeout))
  File "C:\projects\lesson2\learn-homework-1\untitled\lib\site-packages\telegram\utils\request.py", line 309, in post
    headers={'Content-Type': 'application/json'})
  File "C:\projects\lesson2\learn-homework-1\untitled\lib\site-packages\telegram\utils\request.py", line 209, in _request_wrapper
    raise NetworkError('urllib3 HTTPError {0}'.format(error))
telegram.error.NetworkError: urllib3 HTTPError SOCKSHTTPSConnectionPool(host='api.telegram.org', port=443): Max retries exceeded with url: /bot806287477:AAGRPsodiHUxnxz2zWZAUcUeUiTkIaqkMIo/getUpdates (Caused by NewConnectionError('<telegram.vendor.ptb_urllib3.urllib3.contrib.socks.SOCKSHTTPSConnection object at 0x000001FB66809E80>: Failed to establish a new connection: [Errno 11001] getaddrinfo failed',))
telegram.vendor.ptb_urllib3.urllib3.connectionpool - WARNING - Retrying (Retry(total=2, connect=None, read=None, redirect=None)) after connection broken by 'NewConnectionError('<telegram.vendor.ptb_urllib3.urllib3.contrib.socks.SOCKSHTTPSConnection object at 0x000001FB67029EB8>: Failed to establish a new connection: [Errno 11001] getaddrinfo failed',)': /bot806287477:AAGRPsodiHUxnxz2zWZAUcUeUiTkIaqkMIo/getUpdates
telegram.vendor.ptb_urllib3.urllib3.connectionpool - WARNING - Retrying (Retry(total=1, connect=None, read=None, redirect=None)) after connection broken by 'NewConnectionError('<telegram.vendor.ptb_urllib3.urllib3.contrib.socks.SOCKSHTTPSConnection object at 0x000001FB6786D748>: Failed to establish a new connection: [Errno 11001] getaddrinfo failed',)': /bot806287477:AAGRPsodiHUxnxz2zWZAUcUeUiTkIaqkMIo/getUpdates
telegram.vendor.ptb_urllib3.urllib3.connectionpool - WARNING - Retrying (Retry(total=0, connect=None, read=None, redirect=None)) after connection broken by 'NewConnectionError('<telegram.vendor.ptb_urllib3.urllib3.contrib.socks.SOCKSHTTPSConnection object at 0x000001FB6786D978>: Failed to establish a new connection: [Errno 11001] getaddrinfo failed',)': /bot806287477:AAGRPsodiHUxnxz2zWZAUcUeUiTkIaqkMIo/getUpdates
telegram.ext.updater - ERROR - Error while getting Updates: urllib3 HTTPError SOCKSHTTPSConnectionPool(host='api.telegram.org', port=443): Max retries exceeded with url: /bot806287477:AAGRPsodiHUxnxz2zWZAUcUeUiTkIaqkMIo/getUpdates (Caused by NewConnectionError('<telegram.vendor.ptb_urllib3.urllib3.contrib.socks.SOCKSHTTPSConnection object at 0x000001FB6786DCF8>: Failed to establish a new connection: [Errno 11001] getaddrinfo failed',))
telegram.ext.dispatcher - ERROR - No error handlers are registered, logging exception.
Traceback (most recent call last):
  File "C:\projects\lesson2\learn-homework-1\untitled\lib\site-packages\telegram\vendor\ptb_urllib3\urllib3\contrib\socks.py", line 88, in _new_conn
    **extra_kw
  File "C:\projects\lesson2\learn-homework-1\untitled\lib\site-packages\socks.py", line 180, in create_connection
    for r in socket.getaddrinfo(proxy_addr, proxy_port, 0, socket.SOCK_STREAM):
  File "C:\Users\Anna\AppData\Local\Programs\Python\Python36\lib\socket.py", line 745, in getaddrinfo
    for res in _socket.getaddrinfo(host, port, family, type, proto, flags):
socket.gaierror: [Errno 11001] getaddrinfo failed

During handling of the above exception, another exception occurred:

Traceback (most recent call last):
  File "C:\projects\lesson2\learn-homework-1\untitled\lib\site-packages\telegram\vendor\ptb_urllib3\urllib3\connectionpool.py", line 617, in urlopen
    chunked=chunked)
  File "C:\projects\lesson2\learn-homework-1\untitled\lib\site-packages\telegram\vendor\ptb_urllib3\urllib3\connectionpool.py", line 360, in _make_request
    self._validate_conn(conn)
  File "C:\projects\lesson2\learn-homework-1\untitled\lib\site-packages\telegram\vendor\ptb_urllib3\urllib3\connectionpool.py", line 857, in _validate_conn
    super(HTTPSConnectionPool, self)._validate_conn(conn)
  File "C:\projects\lesson2\learn-homework-1\untitled\lib\site-packages\telegram\vendor\ptb_urllib3\urllib3\connectionpool.py", line 289, in _validate_conn
    conn.connect()
  File "C:\projects\lesson2\learn-homework-1\untitled\lib\site-packages\telegram\vendor\ptb_urllib3\urllib3\connection.py", line 284, in connect
    conn = self._new_conn()
  File "C:\projects\lesson2\learn-homework-1\untitled\lib\site-packages\telegram\vendor\ptb_urllib3\urllib3\contrib\socks.py", line 120, in _new_conn
    self, "Failed to establish a new connection: %s" % e)
telegram.vendor.ptb_urllib3.urllib3.exceptions.NewConnectionError: <telegram.vendor.ptb_urllib3.urllib3.contrib.socks.SOCKSHTTPSConnection object at 0x000001FB6786DCF8>: Failed to establish a new connection: [Errno 11001] getaddrinfo failed

During handling of the above exception, another exception occurred:

Traceback (most recent call last):
  File "C:\projects\lesson2\learn-homework-1\untitled\lib\site-packages\telegram\utils\request.py", line 203, in _request_wrapper
    resp = self._con_pool.request(*args, **kwargs)
  File "C:\projects\lesson2\learn-homework-1\untitled\lib\site-packages\telegram\vendor\ptb_urllib3\urllib3\request.py", line 70, in request
    **urlopen_kw)
  File "C:\projects\lesson2\learn-homework-1\untitled\lib\site-packages\telegram\vendor\ptb_urllib3\urllib3\request.py", line 148, in request_encode_body
    return self.urlopen(method, url, **extra_kw)
  File "C:\projects\lesson2\learn-homework-1\untitled\lib\site-packages\telegram\vendor\ptb_urllib3\urllib3\poolmanager.py", line 244, in urlopen
    response = conn.urlopen(method, u.request_uri, **kw)
  File "C:\projects\lesson2\learn-homework-1\untitled\lib\site-packages\telegram\vendor\ptb_urllib3\urllib3\connectionpool.py", line 695, in urlopen
    **response_kw)
  File "C:\projects\lesson2\learn-homework-1\untitled\lib\site-packages\telegram\vendor\ptb_urllib3\urllib3\connectionpool.py", line 695, in urlopen
    **response_kw)
  File "C:\projects\lesson2\learn-homework-1\untitled\lib\site-packages\telegram\vendor\ptb_urllib3\urllib3\connectionpool.py", line 695, in urlopen
    **response_kw)
  File "C:\projects\lesson2\learn-homework-1\untitled\lib\site-packages\telegram\vendor\ptb_urllib3\urllib3\connectionpool.py", line 666, in urlopen
    _stacktrace=sys.exc_info()[2])
  File "C:\projects\lesson2\learn-homework-1\untitled\lib\site-packages\telegram\vendor\ptb_urllib3\urllib3\util\retry.py", line 376, in increment
    raise MaxRetryError(_pool, url, error or ResponseError(cause))
telegram.vendor.ptb_urllib3.urllib3.exceptions.MaxRetryError: SOCKSHTTPSConnectionPool(host='api.telegram.org', port=443): Max retries exceeded with url: /bot806287477:AAGRPsodiHUxnxz2zWZAUcUeUiTkIaqkMIo/getUpdates (Caused by NewConnectionError('<telegram.vendor.ptb_urllib3.urllib3.contrib.socks.SOCKSHTTPSConnection object at 0x000001FB6786DCF8>: Failed to establish a new connection: [Errno 11001] getaddrinfo failed',))

During handling of the above exception, another exception occurred:

Traceback (most recent call last):
  File "C:\projects\lesson2\learn-homework-1\untitled\lib\site-packages\telegram\ext\updater.py", line 319, in _network_loop_retry
    if not action_cb():
  File "C:\projects\lesson2\learn-homework-1\untitled\lib\site-packages\telegram\ext\updater.py", line 280, in polling_action_cb
    allowed_updates=allowed_updates)
  File "C:\projects\lesson2\learn-homework-1\untitled\lib\site-packages\telegram\bot.py", line 65, in decorator
    result = func(self, *args, **kwargs)
  File "C:\projects\lesson2\learn-homework-1\untitled\lib\site-packages\telegram\bot.py", line 1975, in get_updates
    result = self._request.post(url, data, timeout=float(read_latency) + float(timeout))
  File "C:\projects\lesson2\learn-homework-1\untitled\lib\site-packages\telegram\utils\request.py", line 309, in post
    headers={'Content-Type': 'application/json'})
  File "C:\projects\lesson2\learn-homework-1\untitled\lib\site-packages\telegram\utils\request.py", line 209, in _request_wrapper
    raise NetworkError('urllib3 HTTPError {0}'.format(error))
telegram.error.NetworkError: urllib3 HTTPError SOCKSHTTPSConnectionPool(host='api.telegram.org', port=443): Max retries exceeded with url: /bot806287477:AAGRPsodiHUxnxz2zWZAUcUeUiTkIaqkMIo/getUpdates (Caused by NewConnectionError('<telegram.vendor.ptb_urllib3.urllib3.contrib.socks.SOCKSHTTPSConnection object at 0x000001FB6786DCF8>: Failed to establish a new connection: [Errno 11001] getaddrinfo failed',))
telegram.vendor.ptb_urllib3.urllib3.connectionpool - WARNING - Retrying (Retry(total=2, connect=None, read=None, redirect=None)) after connection broken by 'ConnectTimeoutError(<telegram.vendor.ptb_urllib3.urllib3.contrib.socks.SOCKSHTTPSConnection object at 0x000001FB68A4F0F0>, 'Connection to api.telegram.org timed out. (connect timeout=5.0)')': /bot806287477:AAGRPsodiHUxnxz2zWZAUcUeUiTkIaqkMIo/getUpdates
telegram.vendor.ptb_urllib3.urllib3.connectionpool - WARNING - Retrying (Retry(total=2, connect=None, read=None, redirect=None)) after connection broken by 'ConnectTimeoutError(<telegram.vendor.ptb_urllib3.urllib3.contrib.socks.SOCKSHTTPSConnection object at 0x000001FB68A4FBA8>, 'Connection to api.telegram.org timed out. (connect timeout=5.0)')': /bot806287477:AAGRPsodiHUxnxz2zWZAUcUeUiTkIaqkMIo/getUpdates
telegram.vendor.ptb_urllib3.urllib3.connectionpool - WARNING - Retrying (Retry(total=1, connect=None, read=None, redirect=None)) after connection broken by 'ConnectTimeoutError(<telegram.vendor.ptb_urllib3.urllib3.contrib.socks.SOCKSHTTPSConnection object at 0x000001FB68A4FEB8>, 'Connection to api.telegram.org timed out. (connect timeout=5.0)')': /bot806287477:AAGRPsodiHUxnxz2zWZAUcUeUiTkIaqkMIo/getUpdates
telegram.vendor.ptb_urllib3.urllib3.connectionpool - WARNING - Retrying (Retry(total=0, connect=None, read=None, redirect=None)) after connection broken by 'NewConnectionError('<telegram.vendor.ptb_urllib3.urllib3.contrib.socks.SOCKSHTTPSConnection object at 0x000001FB68A4F198>: Failed to establish a new connection: [Errno 11001] getaddrinfo failed',)': /bot806287477:AAGRPsodiHUxnxz2zWZAUcUeUiTkIaqkMIo/getUpdates
telegram.ext.updater - ERROR - Error while getting Updates: urllib3 HTTPError SOCKSHTTPSConnectionPool(host='api.telegram.org', port=443): Max retries exceeded with url: /bot806287477:AAGRPsodiHUxnxz2zWZAUcUeUiTkIaqkMIo/getUpdates (Caused by NewConnectionError('<telegram.vendor.ptb_urllib3.urllib3.contrib.socks.SOCKSHTTPSConnection object at 0x000001FB68A4F940>: Failed to establish a new connection: [Errno 11001] getaddrinfo failed',))
telegram.ext.dispatcher - ERROR - No error handlers are registered, logging exception.
Traceback (most recent call last):
  File "C:\projects\lesson2\learn-homework-1\untitled\lib\site-packages\socks.py", line 809, in connect
    negotiate(self, dest_addr, dest_port)
  File "C:\projects\lesson2\learn-homework-1\untitled\lib\site-packages\socks.py", line 444, in _negotiate_SOCKS5
    self, CONNECT, dest_addr)
  File "C:\projects\lesson2\learn-homework-1\untitled\lib\site-packages\socks.py", line 520, in _SOCKS5_request
    resolved = self._write_SOCKS5_address(dst, writer)
  File "C:\projects\lesson2\learn-homework-1\untitled\lib\site-packages\socks.py", line 576, in _write_SOCKS5_address
    socket.AI_ADDRCONFIG)
  File "C:\Users\Anna\AppData\Local\Programs\Python\Python36\lib\socket.py", line 745, in getaddrinfo
    for res in _socket.getaddrinfo(host, port, family, type, proto, flags):
socket.gaierror: [Errno 11001] getaddrinfo failed

During handling of the above exception, another exception occurred:

Traceback (most recent call last):
  File "C:\projects\lesson2\learn-homework-1\untitled\lib\site-packages\telegram\vendor\ptb_urllib3\urllib3\contrib\socks.py", line 88, in _new_conn
    **extra_kw
  File "C:\projects\lesson2\learn-homework-1\untitled\lib\site-packages\socks.py", line 209, in create_connection
    raise err
  File "C:\projects\lesson2\learn-homework-1\untitled\lib\site-packages\socks.py", line 199, in create_connection
    sock.connect((remote_host, remote_port))
  File "C:\projects\lesson2\learn-homework-1\untitled\lib\site-packages\socks.py", line 47, in wrapper
    return function(*args, **kwargs)
  File "C:\projects\lesson2\learn-homework-1\untitled\lib\site-packages\socks.py", line 814, in connect
    raise GeneralProxyError("Socket error", error)
socks.GeneralProxyError: Socket error: [Errno 11001] getaddrinfo failed

During handling of the above exception, another exception occurred:

Traceback (most recent call last):
  File "C:\projects\lesson2\learn-homework-1\untitled\lib\site-packages\telegram\vendor\ptb_urllib3\urllib3\connectionpool.py", line 617, in urlopen
    chunked=chunked)
  File "C:\projects\lesson2\learn-homework-1\untitled\lib\site-packages\telegram\vendor\ptb_urllib3\urllib3\connectionpool.py", line 360, in _make_request
    self._validate_conn(conn)
  File "C:\projects\lesson2\learn-homework-1\untitled\lib\site-packages\telegram\vendor\ptb_urllib3\urllib3\connectionpool.py", line 857, in _validate_conn
    super(HTTPSConnectionPool, self)._validate_conn(conn)
  File "C:\projects\lesson2\learn-homework-1\untitled\lib\site-packages\telegram\vendor\ptb_urllib3\urllib3\connectionpool.py", line 289, in _validate_conn
    conn.connect()
  File "C:\projects\lesson2\learn-homework-1\untitled\lib\site-packages\telegram\vendor\ptb_urllib3\urllib3\connection.py", line 284, in connect
    conn = self._new_conn()
  File "C:\projects\lesson2\learn-homework-1\untitled\lib\site-packages\telegram\vendor\ptb_urllib3\urllib3\contrib\socks.py", line 110, in _new_conn
    "Failed to establish a new connection: %s" % error
telegram.vendor.ptb_urllib3.urllib3.exceptions.NewConnectionError: <telegram.vendor.ptb_urllib3.urllib3.contrib.socks.SOCKSHTTPSConnection object at 0x000001FB68A4F940>: Failed to establish a new connection: [Errno 11001] getaddrinfo failed

During handling of the above exception, another exception occurred:

Traceback (most recent call last):
  File "C:\projects\lesson2\learn-homework-1\untitled\lib\site-packages\telegram\utils\request.py", line 203, in _request_wrapper
    resp = self._con_pool.request(*args, **kwargs)
  File "C:\projects\lesson2\learn-homework-1\untitled\lib\site-packages\telegram\vendor\ptb_urllib3\urllib3\request.py", line 70, in request
    **urlopen_kw)
  File "C:\projects\lesson2\learn-homework-1\untitled\lib\site-packages\telegram\vendor\ptb_urllib3\urllib3\request.py", line 148, in request_encode_body
    return self.urlopen(method, url, **extra_kw)
  File "C:\projects\lesson2\learn-homework-1\untitled\lib\site-packages\telegram\vendor\ptb_urllib3\urllib3\poolmanager.py", line 244, in urlopen
    response = conn.urlopen(method, u.request_uri, **kw)
  File "C:\projects\lesson2\learn-homework-1\untitled\lib\site-packages\telegram\vendor\ptb_urllib3\urllib3\connectionpool.py", line 695, in urlopen
    **response_kw)
  File "C:\projects\lesson2\learn-homework-1\untitled\lib\site-packages\telegram\vendor\ptb_urllib3\urllib3\connectionpool.py", line 695, in urlopen
    **response_kw)
  File "C:\projects\lesson2\learn-homework-1\untitled\lib\site-packages\telegram\vendor\ptb_urllib3\urllib3\connectionpool.py", line 695, in urlopen
    **response_kw)
  File "C:\projects\lesson2\learn-homework-1\untitled\lib\site-packages\telegram\vendor\ptb_urllib3\urllib3\connectionpool.py", line 666, in urlopen
    _stacktrace=sys.exc_info()[2])
  File "C:\projects\lesson2\learn-homework-1\untitled\lib\site-packages\telegram\vendor\ptb_urllib3\urllib3\util\retry.py", line 376, in increment
    raise MaxRetryError(_pool, url, error or ResponseError(cause))
telegram.vendor.ptb_urllib3.urllib3.exceptions.MaxRetryError: SOCKSHTTPSConnectionPool(host='api.telegram.org', port=443): Max retries exceeded with url: /bot806287477:AAGRPsodiHUxnxz2zWZAUcUeUiTkIaqkMIo/getUpdates (Caused by NewConnectionError('<telegram.vendor.ptb_urllib3.urllib3.contrib.socks.SOCKSHTTPSConnection object at 0x000001FB68A4F940>: Failed to establish a new connection: [Errno 11001] getaddrinfo failed',))

During handling of the above exception, another exception occurred:

Traceback (most recent call last):
  File "C:\projects\lesson2\learn-homework-1\untitled\lib\site-packages\telegram\ext\updater.py", line 319, in _network_loop_retry
    if not action_cb():
  File "C:\projects\lesson2\learn-homework-1\untitled\lib\site-packages\telegram\ext\updater.py", line 280, in polling_action_cb
    allowed_updates=allowed_updates)
  File "C:\projects\lesson2\learn-homework-1\untitled\lib\site-packages\telegram\bot.py", line 65, in decorator
    result = func(self, *args, **kwargs)
  File "C:\projects\lesson2\learn-homework-1\untitled\lib\site-packages\telegram\bot.py", line 1975, in get_updates
    result = self._request.post(url, data, timeout=float(read_latency) + float(timeout))
  File "C:\projects\lesson2\learn-homework-1\untitled\lib\site-packages\telegram\utils\request.py", line 309, in post
    headers={'Content-Type': 'application/json'})
  File "C:\projects\lesson2\learn-homework-1\untitled\lib\site-packages\telegram\utils\request.py", line 209, in _request_wrapper
    raise NetworkError('urllib3 HTTPError {0}'.format(error))
telegram.error.NetworkError: urllib3 HTTPError SOCKSHTTPSConnectionPool(host='api.telegram.org', port=443): Max retries exceeded with url: /bot806287477:AAGRPsodiHUxnxz2zWZAUcUeUiTkIaqkMIo/getUpdates (Caused by NewConnectionError('<telegram.vendor.ptb_urllib3.urllib3.contrib.socks.SOCKSHTTPSConnection object at 0x000001FB68A4F940>: Failed to establish a new connection: [Errno 11001] getaddrinfo failed',))
